<?xml version='1.0'?>
<sdf version='1.4'>
<model name="MSI Rover">
  <static>0</static>

<!------------------------------------------------------------------------------------------>
<!------------------------------------------------------------------------------------------>
<!---------------------------      Chassis Assembly Begins       --------------------------->
<!------------------------------------------------------------------------------------------>
<!------------------------------------------------------------------------------------------>

  <link name='Chassis'>
    <self_collide>0</self_collide>
    <pose>0.0000 0.0000 0.4720 0.0000 0.0000 0.0000</pose>
    <collision name='Chassis_Collision'>
      <pose>0.0000 -0.0120 0.0380 0.0000 0.0000 0.0000</pose>
      <geometry>
        <box>
          <size>0.6100 0.9300 0.1527</size>
        </box>
      </geometry>
<!------------------------------>
<!------------ TODO ------------>
<!-------------------------------
      <surface>
        <bounce>
          <restitution_coefficient>
-------------------------------->
    </collision>
    <visual name='Chassis_Visual'>
      <geometry>
        <mesh>
          <scale>0.0010 0.0010 0.0010</scale>
          <uri>model://msi_rover/meshes/Chassis.STL</uri>
        </mesh>
      </geometry>
<!------------------------------>
<!------------ TODO ------------>
<!-------------------------------
      <material>
        <script>
          <uri>
          <name>
        <shader>
          <normal_map>
        <lighting>
        <ambient>
        <diffuse>
        <specular>
        <emissive>
-------------------------------->
    </visual>
    <inertial>
      <mass>7.259</mass>                                       <!-- Volume = 0.000902 m^3 -->
      <pose>0.0000 -0.0560 0.0013 0.0000 0.0000 0.0000</pose>
      <inertia>
        <ixx> 0.54570278912</ixx>
        <ixy>-0.00003168874</ixy>
        <ixz>-0.00000141851</ixz>
        <iyy> 0.55866375000</iyy>
        <iyz> 0.02659627264</iyz>
        <izz> 1.07370025000</izz>
      </inertia>
    </inertial>
  </link>

  <link name='Lidar'>
    <self_collide>0</self_collide>
    <pose>0 0 0.3 0 -0 1.57079632679</pose>
    <sensor name='laser' type='ray'>
      <pose>0 0 0 0 -0 0</pose>
      <ray>
        <scan>
          <horizontal>
            <samples>180</samples>
            <resolution>1</resolution>
            <min_angle>-3.12413936107</min_angle>
            <max_angle> 3.14159265359</max_angle>
          </horizontal>
        </scan>
        <range>
          <min>0.8</min>
          <max>5.8</max>
          <resolution>0.01</resolution>
        </range>
        </ray>
        <plugin name="laser" filename="libgazebo_ros_laser.so">
          <topicName>/rover/environ_periph</topicName>
          <frameName>scan</frameName>
        </plugin>
        <always_on>1</always_on>
        <update_rate>5</update_rate>
        <visualize>0</visualize>
      </sensor>
    </link>

  <joint type="revolute" name="Lidar_Chassis_Joint">
    <pose>0.0000 0.0000 0.0000 0.0000 0.0000 0.0000</pose>
    <child>Lidar</child>
    <parent>Chassis</parent>
    <axis>
      <xyz>0 0 1</xyz>
<!------------------------------>
<!------------ TODO ------------>
<!-------------------------------
      <dynamics>
        <damping>
        <friction>
      <limit>
        <lower>
        <upper>
        <effort>
        <velocity>
        <stiffness>
        <dissipation>
------------------------------->
    </axis>
<!------------------------------>
<!------------ TODO ------------>
<!-------------------------------
    <physics>
      <ode>
        <provide_feedback>
        <cfm_damping>
        <implicit_spring_damper>
        <fudge_factor>
        <cfm>
        <erp>
        <bounce>
        <max_force>
        <velocity>
        <limit>
          <cfm>
          <erp>
        <suspension>
          <cfm>
          <erp>
------------------------------->
  </joint>


<!------------------------------------------------------------------------------------------>
<!------------------------------------------------------------------------------------------>
<!---------------------------       Chassis Assembly Ends        --------------------------->
<!------------------------------------------------------------------------------------------>
<!------------------------------------------------------------------------------------------>
<!--------------------------- Left Rocker-Bogie Assembly Begins  --------------------------->
<!------------------------------------------------------------------------------------------>
<!------------------------------------------------------------------------------------------>

  <link name='Left_Rocker'>
    <self_collide>0</self_collide>
    <pose>-0.3270 0.0000 0.4720 0.0000 0.0000 0.0000</pose>
<!------------------------------>
<!------------ TODO ------------>
<!-------------------------------
    <collision name='Left_Rocker_Collision'>
      <geometry>
        <mesh>
          <scale>0.0010 0.0010 0.0010</scale>
          <uri>model://msi_rover/meshes/Rocker_L.STL</uri>
        </mesh>
      </geometry>
      <surface>
        <bounce>
          <restitution_coefficient>
    </collision>
-------------------------------->
    <visual name='Left_Rocker_Visual'>
      <geometry>
        <mesh>
          <scale>0.0010 0.0010 0.0010</scale>
          <uri>model://msi_rover/meshes/Rocker_L.STL</uri>
        </mesh>
      </geometry>
<!------------------------------>
<!------------ TODO ------------>
<!-------------------------------
      <material>
        <script>
          <uri>
          <name>
        <shader>
          <normal_map>
        <lighting>
        <ambient>
        <diffuse>
        <specular>
        <emissive>
-------------------------------->
    </visual>
    <inertial>
      <mass>7.704</mass>                                       <!-- Volume = 0.000957 m^3 -->
      <pose>-0.0315 -0.3536 -0.0096 0.0000 0.0000 0.0000</pose>
      <inertia>
        <ixx> 0.60764512256</ixx>
        <ixy>-0.03926894848</ixy>
        <ixz> 0.00231192640</ixz>
        <iyy> 0.01925778048</iyy>
        <iyz> 0.01388497024</iyz>
        <izz> 0.60239790080</izz>
      </inertia>
    </inertial>
  </link>

  <link name='Left_Bogie'>
    <self_collide>0</self_collide>
    <pose>-0.2940 0.1750 0.4320 0.0000 0.0000 0.0000</pose>
<!------------------------------>
<!------------ TODO ------------>
<!-------------------------------
    <collision name='Left_Bogie_Collision'>
      <geometry>
        <mesh>
          <scale>0.0010 0.0010 0.0010</scale>
          <uri>model://msi_rover/meshes/Bogie_L.STL</uri>
        </mesh>
      </geometry>
      <surface>
        <bounce>
          <restitution_coefficient>
    </collision>
-------------------------------->
    <visual name='Left_Bogie_Visual'>
      <geometry>
        <mesh>
          <scale>0.0010 0.0010 0.0010</scale>
          <uri>model://msi_rover/meshes/Bogie_L.STL</uri>
        </mesh>
      </geometry>
<!------------------------------>
<!------------ TODO ------------>
<!-------------------------------
      <material>
        <script>
          <uri>
          <name>
        <shader>
          <normal_map>
        <lighting>
        <ambient>
        <diffuse>
        <specular>
        <emissive>
-------------------------------->
    </visual>
    <inertial>
      <mass>8.493</mass>                                       <!-- Volume = 0.001055 m^3 -->
      <pose>-0.0418 0.0698 -0.0580 0.0000 0.0000 0.0000</pose>
      <inertia>
        <ixx> 0.65631109120</ixx>
        <ixy> 0.00444596320</ixy>
        <ixz>-0.00654497920</ixz>
        <iyy> 0.20716726272</iyy>
        <iyz>-0.27300364288</iyz>
        <izz> 0.48130539520</izz>
      </inertia>
    </inertial>
  </link>

  <link name='Left_Rear_Steering'>
    <self_collide>0</self_collide>
    <pose>-0.3810 -0.4900 0.36800 0.0000 0.0000 0.0000</pose>
<!--
    <collision name='Left_Rear_Steering_Collision'>
      <geometry>
        <mesh>
          <scale>0.0010 0.0010 0.0010</scale>
          <uri>model://msi_rover/meshes/C_Assembly_L.STL</uri>
        </mesh>
      </geometry>
<!-------------------------------
<!------------ TODO -------------
<!-------------------------------
      <surface>
        <bounce>
          <restitution_coefficient>
---------------------------------
    </collision>
-->
    <visual name='Left_Rear_Steering_Visual'>
      <geometry>
        <mesh>
          <scale>0.0010 0.0010 0.0010</scale>
          <uri>model://msi_rover/meshes/C_Assembly_L.STL</uri>
        </mesh>
      </geometry>
<!------------------------------>
<!------------ TODO ------------>
<!-------------------------------
      <material>
        <script>
          <uri>
          <name>
        <shader>
          <normal_map>
        <lighting>
        <ambient>
        <diffuse>
        <specular>
        <emissive>
-------------------------------->
    </visual>
    <inertial>
      <mass>3.34075</mass>                                     <!-- Volume = 0.000415 m^3 -->
      <pose>0.0780 0.0000 -0.1480 0.0000 0.0000 0.0000</pose>
      <inertia>
        <ixx> 0.03486317824</ixx>
        <ixy>-0.00000003196</ixy>
        <ixz> 0.00472688032</ixz>
        <iyy> 0.04927550976</iyy>
        <iyz> 0.00000007500</iyz>
        <izz> 0.02074642688</izz>
      </inertia>
    </inertial>
  </link>

  <link name='Left_Front_Steering'>
    <self_collide>0</self_collide>
    <pose>-0.3480 0.4000 0.3680 0.0000 0.0000 0.0000</pose>
<!--
    <collision name='Left_Front_Steering_Collision'>
      <geometry>
        <mesh>
          <scale>0.0010 0.0010 0.0010</scale>
          <uri>model://msi_rover/meshes/C_Assembly_L.STL</uri>
        </mesh>
      </geometry>
<!-------------------------------
<!------------ TODO -------------
<!-------------------------------
      <surface>
        <bounce>
          <restitution_coefficient>
---------------------------------
    </collision>
-->
    <visual name='Left_Front_Steering_Visual'>
      <geometry>
        <mesh>
          <scale>0.0010 0.0010 0.0010</scale>
          <uri>model://msi_rover/meshes/C_Assembly_L.STL</uri>
        </mesh>
      </geometry>
<!------------------------------>
<!------------ TODO ------------>
<!-------------------------------
      <material>
        <script>
          <uri>
          <name>
        <shader>
          <normal_map>
        <lighting>
        <ambient>
        <diffuse>
        <specular>
        <emissive>
-------------------------------->
    </visual>
    <inertial>
      <mass>3.34075</mass>                                     <!-- Volume = 0.000415 m^3 -->
      <pose>0.0780 0.0000 -0.1480 0.0000 0.0000 0.0000</pose>
      <inertia>
        <ixx> 0.03486317824</ixx>
        <ixy>-0.00000003196</ixy>
        <ixz> 0.00472688032</ixz>
        <iyy> 0.04927550976</iyy>
        <iyz> 0.00000007500</iyz>
        <izz> 0.02074642688</izz>
      </inertia>
    </inertial>
  </link>

  <link name='Left_Rear_Tyre'>
    <self_collide>0</self_collide>
    <pose>-0.3910 -0.4900 0.1500 0.0000 0.0000 0.0000</pose>
    <collision name='Left_Rear_Tyre_Collision'>
      <pose>0.0000 0.0000 0.0000 0.0000 1.5708 0.0000</pose>
      <geometry>
        <cylinder>
          <radius>0.150</radius>
          <length>0.180</length>
        </cylinder>
      </geometry>
      <surface>
      	<friction>
      	    <mu>1.0</mu>
      	    <mu2>1.0</mu2>
      	    <slip1>1.0</slip1>
      	    <slip2>1.0</slip2>
      	  </friction>
      </surface>
<!------------------------------>
<!------------ TODO ------------>
<!-------------------------------
      <surface>
        <bounce>
          <restitution_coefficient>
-------------------------------->
    </collision>
    <visual name='Left_Rear_Tyre_Visual'>
      <geometry>
        <mesh>
          <scale>0.0010 0.0010 0.0010</scale>
          <uri>model://msi_rover/meshes/Tyre.STL</uri>
        </mesh>
      </geometry>
<!------------------------------>
<!------------ TODO ------------>
<!-------------------------------
      <material>
        <script>
          <uri>
          <name>
        <shader>
          <normal_map>
        <lighting>
        <ambient>
        <diffuse>
        <specular>
        <emissive>
-------------------------------->
    </visual>
    <inertial>
      <mass>1.8000</mass>                                      <!-- Volume = 0.011174 m^3 -->
      <pose>0.0000 0.0000 0.0000 0.0000 0.0000 0.0000</pose>
      <inertia>
        <ixx> 1.36747859968</ixx>
        <ixy> 0.00000017629</ixy>
        <ixz> 0.00000074685</ixz>
        <iyy> 0.95944794112</iyy>
        <iyz> 0.00000067468</iyz>
        <izz> 0.95944794112</izz>
      </inertia>
    </inertial>
  </link>

  <link name='Left_Middle_Tyre'>
    <self_collide>0</self_collide>
    <pose>-0.4480 -0.0500 0.1500 0.0000 0.0000 0.0000</pose>
    <collision name='Left_Middle_Tyre_Collision'>
      <pose>0.0000 0.0000 0.0000 0.0000 1.5708 0.0000</pose>
      <geometry>
        <cylinder>
          <radius>0.150</radius>
          <length>0.180</length>
        </cylinder>
      </geometry>
      <surface>
      	<friction>
      	    <mu>1.0</mu>
      	    <mu2>1.0</mu2>
      	    <slip1>1.0</slip1>
      	    <slip2>1.0</slip2>
      	  </friction>
      </surface>
<!------------------------------>
<!------------ TODO ------------>
<!-------------------------------
      <surface>
        <bounce>
          <restitution_coefficient>
------------------------------->
    </collision>
    <visual name='Left_Middle_Tyre_Visual'>
      <geometry>
        <mesh>
          <scale>0.0010 0.0010 0.0010</scale>
          <uri>model://msi_rover/meshes/Tyre.STL</uri>
        </mesh>
      </geometry>
<!------------------------------>
<!------------ TODO ------------>
<!-------------------------------
      <material>
        <script>
          <uri>
          <name>
        <shader>
          <normal_map>
        <lighting>
        <ambient>
        <diffuse>
        <specular>
        <emissive>
------------------------------->
    </visual>
    <inertial>
      <mass>1.8000</mass>                                      <!-- Volume = 0.011174 m^3 -->
      <pose>0.0000 0.0000 0.0000 0.0000 0.0000 0.0000</pose>
      <inertia>
        <ixx> 1.36747859968</ixx>
        <ixy> 0.00000017629</ixy>
        <ixz> 0.00000074685</ixz>
        <iyy> 0.95944794112</iyy>
        <iyz> 0.00000067468</iyz>
        <izz> 0.95944794112</izz>
      </inertia>
    </inertial>
  </link>

  <link name='Left_Front_Tyre'>
    <self_collide>0</self_collide>
    <pose>-0.3580 0.4000 0.1500 0.0000 0.0000 0.0000</pose>
    <collision name='Left_Front_Tyre_Collision'>
      <pose>0.0000 0.0000 0.0000 0.0000 1.5708 0.0000</pose>
      <geometry>
        <cylinder>
          <radius>0.150</radius>
          <length>0.180</length>
        </cylinder>
      </geometry>
      <surface>
      	<friction>
      	    <mu>1.0</mu>
      	    <mu2>1.0</mu2>
      	    <slip1>1.0</slip1>
      	    <slip2>1.0</slip2>
      	  </friction>
      </surface>
<!------------------------------>
<!------------ TODO ------------>
<!-------------------------------
      <surface>
        <bounce>
          <restitution_coefficient>
------------------------------->
    </collision>
    <visual name='Left_Front_Tyre_Visual'>
      <geometry>
        <mesh>
          <scale>0.0010 0.0010 0.0010</scale>
          <uri>model://msi_rover/meshes/Tyre.STL</uri>
        </mesh>
      </geometry>
<!------------------------------>
<!------------ TODO ------------>
<!-------------------------------
      <material>
        <script>
          <uri>
          <name>
        <shader>
          <normal_map>
        <lighting>
        <ambient>
        <diffuse>
        <specular>
        <emissive>
------------------------------->
    </visual>
    <inertial>
      <mass>1.8000</mass>                                      <!-- Volume = 0.011174 m^3 -->
      <pose>0.0000 0.0000 0.0000 0.0000 0.0000 0.0000</pose>
      <inertia>
        <ixx> 1.36747859968</ixx>
        <ixy> 0.00000017629</ixy>
        <ixz> 0.00000074685</ixz>
        <iyy> 0.95944794112</iyy>
        <iyz> 0.00000067468</iyz>
        <izz> 0.95944794112</izz>
      </inertia>
    </inertial>
  </link>

<!------------------------------------------------------------------------------------------>
<!---------------------------         Joints Subsection          --------------------------->
<!------------------------------------------------------------------------------------------>

  <joint type="revolute" name="Left_Rocker_Joint">
    <pose>0.0000 0.0000 0.0000 0.0000 0.0000 0.0000</pose>
    <child>Left_Rocker</child>
    <parent>Chassis</parent>
    <axis>
      <xyz>1 0 0</xyz>
<!------------------------------>
<!------------ TODO ------------>
<!-------------------------------
      <dynamics>
        <damping>
        <friction>
      <limit>
        <lower>
        <upper>
        <effort>
        <velocity>
        <stiffness>
        <dissipation>
------------------------------->
    </axis>
<!------------------------------>
<!------------ TODO ------------>
<!-------------------------------
    <physics>
      <ode>
        <provide_feedback>
        <cfm_damping>
        <implicit_spring_damper>
        <fudge_factor>
        <cfm>
        <erp>
        <bounce>
        <max_force>
        <velocity>
        <limit>
          <cfm>
          <erp>
        <suspension>
          <cfm>
          <erp>
------------------------------->
  </joint>

  <joint type="revolute" name="Left_Bogie_Joint">
    <pose>0.0000 0.0000 0.0000 0.0000 0.0000 0.0000</pose>
    <child>Left_Bogie</child>
    <parent>Left_Rocker</parent>
    <axis>
      <xyz>1 0 0</xyz>
      <limit>
        <lower>-0.7</lower>
        <upper>0.7</upper>
      </limit>
<!------------------------------>
<!------------ TODO ------------>
<!-------------------------------
      <dynamics>
        <damping>
        <friction>
      <limit>
        <effort>
        <velocity>
        <stiffness>
        <dissipation>
------------------------------->
    </axis>
<!------------------------------>
<!------------ TODO ------------>
<!-------------------------------
    <physics>
      <ode>
        <provide_feedback>
        <cfm_damping>
        <implicit_spring_damper>
        <fudge_factor>
        <cfm>
        <erp>
        <bounce>
        <max_force>
        <velocity>
        <limit>
          <cfm>
          <erp>
        <suspension>
          <cfm>
          <erp>
------------------------------->
  </joint>

  <joint type="revolute" name="Left_Rear_Steering_Joint">
    <pose>0.0000 0.0000 0.0000 0.0000 0.0000 0.0000</pose>
    <child>Left_Rear_Steering</child>
    <parent>Left_Rocker</parent>
    <axis>
      <xyz>0 0 -1</xyz>
<!------------------------------>
<!------------ TODO ------------>
<!------------------------------>
      <limit>
        <lower>0</lower>
        <upper>0</upper>
      </limit>
<!------------------------------>
<!------------ TODO ------------>
<!-------------------------------
      <dynamics>
        <damping>
        <friction>
      <limit>
        <lower>
        <upper>
        <effort>
        <velocity>
        <stiffness>
        <dissipation>
------------------------------->
    </axis>
<!------------------------------>
<!------------ TODO ------------>
<!-------------------------------
    <physics>
      <ode>
        <provide_feedback>
        <cfm_damping>
        <implicit_spring_damper>
        <fudge_factor>
        <cfm>
        <erp>
        <bounce>
        <max_force>
        <velocity>
        <limit>
          <cfm>
          <erp>
        <suspension>
          <cfm>
          <erp>
------------------------------->
  </joint>

  <joint type="revolute" name="Left_Front_Steering_Joint">
    <pose>0.0000 0.0000 0.0000 0.0000 0.0000 0.0000</pose>
    <child>Left_Front_Steering</child>
    <parent>Left_Bogie</parent>
    <axis>
      <xyz>0 0 -1</xyz>
<!------------------------------>
<!------------ TODO ------------>
<!------------------------------>
      <limit>
        <lower>0</lower>
        <upper>0</upper>
      </limit>
<!------------------------------>
<!------------ TODO ------------>
<!-------------------------------
      <dynamics>
        <damping>
        <friction>
      <limit>
        <lower>
        <upper>
        <effort>
        <velocity>
        <stiffness>
        <dissipation>
------------------------------->
    </axis>
<!------------------------------>
<!------------ TODO ------------>
<!-------------------------------
    <physics>
      <ode>
        <provide_feedback>
        <cfm_damping>
        <implicit_spring_damper>
        <fudge_factor>
        <cfm>
        <erp>
        <bounce>
        <max_force>
        <velocity>
        <limit>
          <cfm>
          <erp>
        <suspension>
          <cfm>
          <erp>
------------------------------->
  </joint>

  <joint type="revolute" name="Left_Rear_Tyre_Joint">
    <pose>0.0000 0.0000 0.0000 0.0000 0.0000 0.0000</pose>
    <child>Left_Rear_Tyre</child>
    <parent>Left_Rear_Steering</parent>
    <axis>
      <xyz>1 0 0</xyz>
      <dynamics>
      	<friction>1.0</friction>
      </dynamics>
<!------------------------------>
<!------------ TODO ------------>
<!-------------------------------
      <dynamics>
        <damping>
        <friction>
      <limit>
        <lower>
        <upper>
        <effort>
        <velocity>
        <stiffness>
        <dissipation>
------------------------------->
    </axis>
<!------------------------------>
<!------------ TODO ------------>
<!-------------------------------
    <physics>
      <ode>
        <provide_feedback>
        <cfm_damping>
        <implicit_spring_damper>
        <fudge_factor>
        <cfm>
        <erp>
        <bounce>
        <max_force>
        <velocity>
        <limit>
          <cfm>
          <erp>
        <suspension>
          <cfm>
          <erp>
------------------------------->
  </joint>

  <joint type="revolute" name="Left_Middle_Tyre_Joint">
    <pose>0.0000 0.0000 0.0000 0.0000 0.0000 0.0000</pose>
    <child>Left_Middle_Tyre</child>
    <parent>Left_Bogie</parent>
    <axis>
      <xyz>1 0 0</xyz>
      <dynamics>
      	<friction>1.0</friction>
      </dynamics>
<!------------------------------>
<!------------ TODO ------------>
<!-------------------------------
      <dynamics>
        <damping>
        <friction>
      <limit>
        <lower>
        <upper>
        <effort>
        <velocity>
        <stiffness>
        <dissipation>
------------------------------->
    </axis>
<!------------------------------>
<!------------ TODO ------------>
<!-------------------------------
    <physics>
      <ode>
        <provide_feedback>
        <cfm_damping>
        <implicit_spring_damper>
        <fudge_factor>
        <cfm>
        <erp>
        <bounce>
        <max_force>
        <velocity>
        <limit>
          <cfm>
          <erp>
        <suspension>
          <cfm>
          <erp>
------------------------------->
  </joint>

  <joint type="revolute" name="Left_Front_Tyre_Joint">
    <pose>0.0000 0.0000 0.0000 0.0000 0.0000 0.0000</pose>
    <child>Left_Front_Tyre</child>
    <parent>Left_Front_Steering</parent>
    <axis>
      <xyz>1 0 0</xyz>
      <dynamics>
      	<friction>1.0</friction>
      </dynamics>
<!------------------------------>
<!------------ TODO ------------>
<!-------------------------------
      <dynamics>
        <damping>
        <friction>
      <limit>
        <lower>
        <upper>
        <effort>
        <velocity>
        <stiffness>
        <dissipation>
------------------------------->
    </axis>
<!------------------------------>
<!------------ TODO ------------>
<!-------------------------------
    <physics>
      <ode>
        <provide_feedback>
        <cfm_damping>
        <implicit_spring_damper>
        <fudge_factor>
        <cfm>
        <erp>
        <bounce>
        <max_force>
        <velocity>
        <limit>
          <cfm>
          <erp>
        <suspension>
          <cfm>
          <erp>
------------------------------->
  </joint>

<!------------------------------------------------------------------------------------------>
<!------------------------------------------------------------------------------------------>
<!---------------------------  Left Rocker-Bogie Assembly Ends   --------------------------->
<!------------------------------------------------------------------------------------------>
<!------------------------------------------------------------------------------------------>
<!--------------------------- Right Rocker-Bogie Assembly Begins --------------------------->
<!------------------------------------------------------------------------------------------>
<!------------------------------------------------------------------------------------------>

  <link name='Right_Rocker'>
    <self_collide>0</self_collide>
    <pose>0.3270 0.0000 0.4720 0.0000 0.0000 0.0000</pose>
<!------------------------------>
<!------------ TODO ------------>
<!-------------------------------
    <collision name='Right_Rocker_Collision'>
      <geometry>
        <mesh>
          <scale>0.0010 0.0010 0.0010</scale>
          <uri>model://msi_rover/meshes/Rocker_R.STL</uri>
        </mesh>
      </geometry>
      <surface>
        <bounce>
          <restitution_coefficient>
    </collision>
------------------------------->
    <visual name='Right_Rocker_Visual'>
      <geometry>
        <mesh>
          <scale>0.0010 0.0010 0.0010</scale>
          <uri>model://msi_rover/meshes/Rocker_R.STL</uri>
        </mesh>
      </geometry>
<!------------------------------>
<!------------ TODO ------------>
<!-------------------------------
      <material>
        <script>
          <uri>
          <name>
        <shader>
          <normal_map>
        <lighting>
        <ambient>
        <diffuse>
        <specular>
        <emissive>
------------------------------->
    </visual>
    <inertial>
      <mass>7.704</mass>                                       <!-- Volume = 0.000957 m^3 -->
      <pose>0.0315 -0.3536 -0.0096 0.0000 0.0000 0.0000</pose>
      <inertia>
        <ixx> 0.60764512256</ixx>
        <ixy> 0.03926894848</ixy>
        <ixz>-0.00231192640</ixz>
        <iyy> 0.01925778048</iyy>
        <iyz> 0.01388497024</iyz>
        <izz> 0.60239790080</izz>
      </inertia>
    </inertial>
  </link>

  <link name='Right_Bogie'>
    <self_collide>0</self_collide>
    <pose>0.2940 0.1750 0.4320 0.0000 0.0000 0.0000</pose>
<!------------------------------>
<!------------ TODO ------------>
<!-------------------------------
    <collision name='Right_Bogie_Collision'>
      <geometry>
        <mesh>
          <scale>0.0010 0.0010 0.0010</scale>
          <uri>model://msi_rover/meshes/Bogie_R.STL</uri>
        </mesh>
      </geometry>
      <surface>
        <bounce>
          <restitution_coefficient>
    </collision>
------------------------------->
    <visual name='Right_Bogie_Visual'>
      <geometry>
        <mesh>
          <scale>0.0010 0.0010 0.0010</scale>
          <uri>model://msi_rover/meshes/Bogie_R.STL</uri>
        </mesh>
      </geometry>
<!------------------------------>
<!------------ TODO ------------>
<!-------------------------------
      <material>
        <script>
          <uri>
          <name>
        <shader>
          <normal_map>
        <lighting>
        <ambient>
        <diffuse>
        <specular>
        <emissive>
------------------------------->
    </visual>
    <inertial>
      <mass>8.493</mass>                                       <!-- Volume = 0.001055 m^3 -->
      <pose>0.0418 0.0698 -0.0580 0.0000 0.0000 0.0000</pose>
      <inertia>
        <ixx> 0.65631109120</ixx>
        <ixy>-0.00444596320</ixy>
        <ixz> 0.00654497920</ixz>
        <iyy> 0.20716726272</iyy>
        <iyz>-0.27300364288</iyz>
        <izz> 0.48130539520</izz>
      </inertia>
    </inertial>
  </link>

  <link name='Right_Rear_Steering'>
    <self_collide>0</self_collide>
    <pose>0.3810 -0.4900 0.3680 0.0000 0.0000 0.0000</pose>
<!--
    <collision name='Right_Rear_Steering_Collision'>
      <geometry>
        <mesh>
          <scale>0.0010 0.0010 0.0010</scale>
          <uri>model://msi_rover/meshes/C_Assembly_R.STL</uri>
        </mesh>
      </geometry>
<!-------------------------------
<!------------ TODO -------------
<!-------------------------------
      <surface>
        <bounce>
          <restitution_coefficient>
--------------------------------
    </collision>
-->
    <visual name='Right_Rear_Steering_Visual'>
      <geometry>
        <mesh>
          <scale>0.0010 0.0010 0.0010</scale>
          <uri>model://msi_rover/meshes/C_Assembly_R.STL</uri>
        </mesh>
      </geometry>
<!------------------------------>
<!------------ TODO ------------>
<!-------------------------------
      <material>
        <script>
          <uri>
          <name>
        <shader>
          <normal_map>
        <lighting>
        <ambient>
        <diffuse>
        <specular>
        <emissive>
------------------------------->
    </visual>
    <inertial>
      <mass>3.34075</mass>                                     <!-- Volume = 0.000415 m^3 -->
      <pose>-0.0780 0.0000 -0.1480 0.0000 0.0000 0.0000</pose>
      <inertia>
        <ixx> 0.03486317824</ixx>
        <ixy>-0.00000003196</ixy>
        <ixz>-0.00472688032</ixz>
        <iyy> 0.04927550976</iyy>
        <iyz>-0.00000007500</iyz>
        <izz> 0.02074642688</izz>
      </inertia>
    </inertial>
  </link>

  <link name='Right_Front_Steering'>
    <self_collide>0</self_collide>
    <pose>0.3480 0.4000 0.3680 0.0000 0.0000 0.0000</pose>
<!------------------------------>
<!------------ TODO ------------>
<!-------------------------------
    <collision name='Right_Front_Steering_Collision'>
      <geometry>
        <mesh>
          <scale>0.0010 0.0010 0.0010</scale>
          <uri>model://msi_rover/meshes/C_Assembly_R.STL</uri>
        </mesh>
      </geometry>
      <surface>
        <bounce>
          <restitution_coefficient>
    </collision>
------------------------------->
    <visual name='Right_Front_Steering_Visual'>
      <geometry>
        <mesh>
          <scale>0.0010 0.0010 0.0010</scale>
          <uri>model://msi_rover/meshes/C_Assembly_R.STL</uri>
        </mesh>
      </geometry>
<!------------------------------>
<!------------ TODO ------------>
<!-------------------------------
      <material>
        <script>
          <uri>
          <name>
        <shader>
          <normal_map>
        <lighting>
        <ambient>
        <diffuse>
        <specular>
        <emissive>
------------------------------->
    </visual>
    <inertial>
      <mass>3.34075</mass>                                     <!-- Volume = 0.000415 m^3 -->
      <pose>-0.0780 0.0000 -0.1480 0.0000 0.0000 0.0000</pose>
      <inertia>
        <ixx> 0.03486317824</ixx>
        <ixy>-0.00000003196</ixy>
        <ixz>-0.00472688032</ixz>
        <iyy> 0.04927550976</iyy>
        <iyz>-0.00000007500</iyz>
        <izz> 0.02074642688</izz>
      </inertia>
    </inertial>
  </link>

  <link name='Right_Rear_Tyre'>
    <self_collide>0</self_collide>
    <pose>0.3910 -0.4900 0.1500 0.0000 0.0000 0.0000</pose>
    <collision name='Right_Rear_Tyre_Collision'>
      <pose>0.0000 0.0000 0.0000 0.0000 1.5708 0.0000</pose>
      <geometry>
        <cylinder>
          <radius>0.150</radius>
          <length>0.180</length>
        </cylinder>
      </geometry>
      <surface>
      	<friction>
      	    <mu>1.0</mu>
      	    <mu2>1.0</mu2>
      	    <slip1>1.0</slip1>
      	    <slip2>1.0</slip2>
      	  </friction>
      </surface>
<!------------------------------>
<!------------ TODO ------------>
<!-------------------------------
      <surface>
        <bounce>
          <restitution_coefficient>
------------------------------->
    </collision>
    <visual name='Right_Rear_Tyre_Visual'>
      <geometry>
        <mesh>
          <scale>0.0010 0.0010 0.0010</scale>
          <uri>model://msi_rover/meshes/Tyre.STL</uri>
        </mesh>
      </geometry>
<!------------------------------>
<!------------ TODO ------------>
<!-------------------------------
      <material>
        <script>
          <uri>
          <name>
        <shader>
          <normal_map>
        <lighting>
        <ambient>
        <diffuse>
        <specular>
        <emissive>
------------------------------->
    </visual>
    <inertial>
      <mass>1.8000</mass>                                      <!-- Volume = 0.011174 m^3 -->
      <pose>0.0000 0.0000 0.0000 0.0000 0.0000 0.0000</pose>
      <inertia>
        <ixx> 1.36747859968</ixx>
        <ixy> 0.00000017629</ixy>
        <ixz> 0.00000074685</ixz>
        <iyy> 0.95944794112</iyy>
        <iyz> 0.00000067468</iyz>
        <izz> 0.95944794112</izz>
      </inertia>
    </inertial>
  </link>

  <link name='Right_Middle_Tyre'>
    <self_collide>0</self_collide>
    <pose>0.4480 -0.0500 0.1500 0.0000 0.0000 0.0000</pose>
    <collision name='Right_Middle_Tyre_Collision'>
      <pose>0.0000 0.0000 0.0000 0.0000 1.5708 0.0000</pose>
      <geometry>
        <cylinder>
          <radius>0.150</radius>
          <length>0.180</length>
        </cylinder>
      </geometry>
      <surface>
      	<friction>
      	    <mu>1.0</mu>
      	    <mu2>1.0</mu2>
      	    <slip1>1.0</slip1>
      	    <slip2>1.0</slip2>
      	  </friction>
      </surface>
<!------------------------------>
<!------------ TODO ------------>
<!-------------------------------
      <surface>
        <bounce>
          <restitution_coefficient>
------------------------------->
    </collision>
    <visual name='Right_Middle_Tyre_Visual'>
      <geometry>
        <mesh>
          <scale>0.0010 0.0010 0.0010</scale>
          <uri>model://msi_rover/meshes/Tyre.STL</uri>
        </mesh>
      </geometry>
<!------------------------------>
<!------------ TODO ------------>
<!-------------------------------
      <material>
        <script>
          <uri>
          <name>
        <shader>
          <normal_map>
        <lighting>
        <ambient>
        <diffuse>
        <specular>
        <emissive>
------------------------------->
    </visual>
    <inertial>
      <mass>1.8000</mass>                                      <!-- Volume = 0.011174 m^3 -->
      <pose>0.0000 0.0000 0.0000 0.0000 0.0000 0.0000</pose>
      <inertia>
        <ixx> 1.36747859968</ixx>
        <ixy> 0.00000017629</ixy>
        <ixz> 0.00000074685</ixz>
        <iyy> 0.95944794112</iyy>
        <iyz> 0.00000067468</iyz>
        <izz> 0.95944794112</izz>
      </inertia>
    </inertial>
  </link>

  <link name='Right_Front_Tyre'>
    <self_collide>0</self_collide>
    <pose>0.3580 0.4000 0.1500 0.0000 0.0000 0.0000</pose>
    <collision name='Right_Front_Tyre_Collision'>
      <pose>0.0000 0.0000 0.0000 0.0000 1.5708 0.0000</pose>
      <geometry>
        <cylinder>
          <radius>0.150</radius>
          <length>0.180</length>
        </cylinder>
      </geometry>
      <surface>
      	<friction>
      	    <mu>1.0</mu>
      	    <mu2>1.0</mu2>
      	    <slip1>1.0</slip1>
      	    <slip2>1.0</slip2>
      	  </friction>
      </surface>
<!------------------------------>
<!------------ TODO ------------>
<!-------------------------------
      <surface>
        <bounce>
          <restitution_coefficient>
------------------------------->
    </collision>
    <visual name='Right_Front_Tyre_Visual'>
      <geometry>
        <mesh>
          <scale>0.0010 0.0010 0.0010</scale>
          <uri>model://msi_rover/meshes/Tyre.STL</uri>
        </mesh>
      </geometry>
<!------------------------------>
<!------------ TODO ------------>
<!-------------------------------
      <material>
        <script>
          <uri>
          <name>
        <shader>
          <normal_map>
        <lighting>
        <ambient>
        <diffuse>
        <specular>
        <emissive>
------------------------------->
    </visual>
    <inertial>
      <mass>1.8000</mass>                                      <!-- Volume = 0.011174 m^3 -->
      <pose>0.0000 0.0000 0.0000 0.0000 0.0000 0.0000</pose>
      <inertia>
        <ixx> 1.36747859968</ixx>
        <ixy> 0.00000017629</ixy>
        <ixz> 0.00000074685</ixz>
        <iyy> 0.95944794112</iyy>
        <iyz> 0.00000067468</iyz>
        <izz> 0.95944794112</izz>
      </inertia>
    </inertial>
  </link>

<!------------------------------------------------------------------------------------------>
<!---------------------------         Joints Subsection          --------------------------->
<!------------------------------------------------------------------------------------------>

  <joint type="revolute" name="Right_Rocker_Joint">
    <pose>0.0000 0.0000 0.0000 0.0000 0.0000 0.0000</pose>
    <child>Right_Rocker</child>
    <parent>Chassis</parent>
    <axis>
      <xyz>1 0 0</xyz>
<!------------------------------>
<!------------ TODO ------------>
<!-------------------------------
      <dynamics>
        <damping>
        <friction>
      <limit>
        <lower>
        <upper>
        <effort>
        <velocity>
        <stiffness>
        <dissipation>
------------------------------->
    </axis>
<!------------------------------>
<!------------ TODO ------------>
<!-------------------------------
    <physics>
      <ode>
        <provide_feedback>
        <cfm_damping>
        <implicit_spring_damper>
        <fudge_factor>
        <cfm>
        <erp>
        <bounce>
        <max_force>
        <velocity>
        <limit>
          <cfm>
          <erp>
        <suspension>
          <cfm>
          <erp>
------------------------------->
  </joint>

  <joint type="revolute" name="Right_Bogie_Joint">
    <pose>0.0000 0.0000 0.0000 0.0000 0.0000 0.0000</pose>
    <child>Right_Bogie</child>
    <parent>Right_Rocker</parent>
    <axis>
      <xyz>1 0 0</xyz>
      <limit>
        <lower>-0.7</lower>
        <upper>0.7</upper>
      </limit>
<!------------------------------>
<!------------ TODO ------------>
<!-------------------------------
      <dynamics>
        <damping>
        <friction>
      <limit>
        <effort>
        <velocity>
        <stiffness>
        <dissipation>
------------------------------->
    </axis>
<!------------------------------>
<!------------ TODO ------------>
<!-------------------------------
    <physics>
      <ode>
        <provide_feedback>
        <cfm_damping>
        <implicit_spring_damper>
        <fudge_factor>
        <cfm>
        <erp>
        <bounce>
        <max_force>
        <velocity>
        <limit>
          <cfm>
          <erp>
        <suspension>
          <cfm>
          <erp>
------------------------------->
  </joint>

  <joint type="revolute" name="Right_Rear_Steering_Joint">
    <pose>0.0000 0.0000 0.0000 0.0000 0.0000 0.0000</pose>
    <child>Right_Rear_Steering</child>
    <parent>Right_Rocker</parent>
    <axis>
      <xyz>0 0 -1</xyz>
<!------------------------------>
<!------------ TODO ------------>
<!------------------------------>
      <limit>
        <lower>0</lower>
        <upper>0</upper>
      </limit>
<!------------------------------>
<!------------ TODO ------------>
<!-------------------------------
      <dynamics>
        <damping>
        <friction>
      <limit>
        <lower>
        <upper>
        <effort>
        <velocity>
        <stiffness>
        <dissipation>
------------------------------->
    </axis>
<!------------------------------>
<!------------ TODO ------------>
<!-------------------------------
    <physics>
      <ode>
        <provide_feedback>
        <cfm_damping>
        <implicit_spring_damper>
        <fudge_factor>
        <cfm>
        <erp>
        <bounce>
        <max_force>
        <velocity>
        <limit>
          <cfm>
          <erp>
        <suspension>
          <cfm>
          <erp>
------------------------------->
  </joint>

  <joint type="revolute" name="Right_Front_Steering_Joint">
    <pose>0.0000 0.0000 0.0000 0.0000 0.0000 0.0000</pose>
    <child>Right_Front_Steering</child>
    <parent>Right_Bogie</parent>
    <axis>
      <xyz>0 0 -1</xyz>
<!------------------------------>
<!------------ TODO ------------>
<!------------------------------>
      <limit>
        <lower>0</lower>
        <upper>0</upper>
      </limit>
<!------------------------------>
<!------------ TODO ------------>
<!-------------------------------
      <dynamics>
        <damping>
        <friction>
      <limit>
        <lower>
        <upper>
        <effort>
        <velocity>
        <stiffness>
        <dissipation>
------------------------------->
    </axis>
<!------------------------------>
<!------------ TODO ------------>
<!-------------------------------
    <physics>
      <ode>
        <provide_feedback>
        <cfm_damping>
        <implicit_spring_damper>
        <fudge_factor>
        <cfm>
        <erp>
        <bounce>
        <max_force>
        <velocity>
        <limit>
          <cfm>
          <erp>
        <suspension>
          <cfm>
          <erp>
------------------------------->
  </joint>

  <joint type="revolute" name="Right_Rear_Tyre_Joint">
    <pose>0.0000 0.0000 0.0000 0.0000 0.0000 0.0000</pose>
    <child>Right_Rear_Tyre</child>
    <parent>Right_Rear_Steering</parent>
    <axis>
      <xyz>1 0 0</xyz>
      <dynamics>
      	<friction>1.0</friction>
      </dynamics>
<!------------------------------>
<!------------ TODO ------------>
<!-------------------------------
      <dynamics>
        <damping>
        <friction>
      <limit>
        <lower>
        <upper>
        <effort>
        <velocity>
        <stiffness>
        <dissipation>
------------------------------->
    </axis>
<!------------------------------>
<!------------ TODO ------------>
<!-------------------------------
    <physics>
      <ode>
        <provide_feedback>
        <cfm_damping>
        <implicit_spring_damper>
        <fudge_factor>
        <cfm>
        <erp>
        <bounce>
        <max_force>
        <velocity>
        <limit>
          <cfm>
          <erp>
        <suspension>
          <cfm>
          <erp>
------------------------------->
  </joint>

  <joint type="revolute" name="Right_Middle_Tyre_Joint">
    <pose>0.0000 0.0000 0.0000 0.0000 0.0000 0.0000</pose>
    <child>Right_Middle_Tyre</child>
    <parent>Right_Bogie</parent>
    <axis>
      <xyz>1 0 0</xyz>
      <dynamics>
      	<friction>1.0</friction>
      </dynamics>
<!------------------------------>
<!------------ TODO ------------>
<!-------------------------------
      <dynamics>
        <damping>
        <friction>
      <limit>
        <lower>
        <upper>
        <effort>
        <velocity>
        <stiffness>
        <dissipation>
------------------------------->
    </axis>
<!------------------------------>
<!------------ TODO ------------>
<!-------------------------------
    <physics>
      <ode>
        <provide_feedback>
        <cfm_damping>
        <implicit_spring_damper>
        <fudge_factor>
        <cfm>
        <erp>
        <bounce>
        <max_force>
        <velocity>
        <limit>
          <cfm>
          <erp>
        <suspension>
          <cfm>
          <erp>
------------------------------->
  </joint>

  <joint type="revolute" name="Right_Front_Tyre_Joint">
    <pose>0.0000 0.0000 0.0000 0.0000 0.0000 0.0000</pose>
    <child>Right_Front_Tyre</child>
    <parent>Right_Front_Steering</parent>
    <axis>
      <xyz>1 0 0</xyz>
      <dynamics>
      	<friction>1.0</friction>
      </dynamics>
<!------------------------------>
<!------------ TODO ------------>
<!-------------------------------
      <dynamics>
        <damping>
        <friction>
      <limit>
        <lower>
        <upper>
        <effort>
        <velocity>
        <stiffness>
        <dissipation>
------------------------------->
    </axis>
<!------------------------------>
<!------------ TODO ------------>
<!-------------------------------
    <physics>
      <ode>
        <provide_feedback>
        <cfm_damping>
        <implicit_spring_damper>
        <fudge_factor>
        <cfm>
        <erp>
        <bounce>
        <max_force>
        <velocity>
        <limit>
          <cfm>
          <erp>
        <suspension>
          <cfm>
          <erp>
------------------------------->
  </joint>

<!------------------------------------------------------------------------------------------>
<!------------------------------------------------------------------------------------------>
<!---------------------------  Right Rocker-Bogie Assembly Ends  --------------------------->
<!------------------------------------------------------------------------------------------>
<!------------------------------------------------------------------------------------------>
<!---------------------------  Triangle Support Assembly Begins  --------------------------->
<!------------------------------------------------------------------------------------------>
<!------------------------------------------------------------------------------------------>
<!------------------------  TODO: REPAIR AND COMPLETE THIS ASSEMBLY ------------------------>
<!------------------------------------------------------------------------------------------>
<!------------------------------------------------------------------------------------------>

  <link name='Left_Triangle'>
    <self_collide>0</self_collide>
    <pose>-0.0720 -0.4800 0.5820 0.0000 0.0000 0.0000</pose>
    <collision name='Left_Triangle_Collision'>
      <geometry>
        <mesh>
          <scale>0.0010 0.0010 0.0010</scale>
          <uri>model://msi_rover/meshes/Triangle_L.STL</uri>
        </mesh>
      </geometry>
<!------------------------------>
<!------------ TODO ------------>
<!-------------------------------
      <surface>
        <bounce>
          <restitution_coefficient>
-------------------------------->
    </collision>
    <visual name='Left_Triangle_Visual'>
      <geometry>
        <mesh>
          <scale>0.0010 0.0010 0.0010</scale>
          <uri>model://msi_rover/meshes/Triangle_L.STL</uri>
        </mesh>
      </geometry>
<!------------------------------>
<!------------ TODO ------------>
<!-------------------------------
      <material>
        <script>
          <uri>
          <name>
        <shader>
          <normal_map>
        <lighting>
        <ambient>
        <diffuse>
        <specular>
        <emissive>
-------------------------------->
    </visual>
    <inertial>
      <mass>1.183</mass>                                       <!-- Volume = 0.000147 m^3 -->
      <pose>-0.0732 -0.0060 -0.0464 0.0000 0.0000 0.0000</pose>
      <inertia>
        <ixx> 0.00518080064</ixx>
        <ixy> 0.00000192063</ixy>
        <ixz> 0.00239985552</ixz>
        <iyy> 0.01473344640</iyy>
        <iyz> 0.00000121663</iyz>
        <izz> 0.00958800384</izz>
      </inertia>
    </inertial>
  </link>

  <link name='Right_Triangle'>
    <self_collide>0</self_collide>
    <pose>0.0720 -0.4800 0.5820 0.0000 0.0000 0.0000</pose>
    <collision name='Right_Triangle_Collision'>
      <geometry>
        <mesh>
          <scale>0.0010 0.0010 0.0010</scale>
          <uri>model://msi_rover/meshes/Triangle_R.STL</uri>
        </mesh>
      </geometry>
<!------------------------------>
<!------------ TODO ------------>
<!-------------------------------
      <surface>
        <bounce>
          <restitution_coefficient>
-------------------------------->
    </collision>
    <visual name='Right_Triangle_Visual'>
      <geometry>
        <mesh>
          <scale>0.0010 0.0010 0.0010</scale>
          <uri>model://msi_rover/meshes/Triangle_R.STL</uri>
        </mesh>
      </geometry>
<!------------------------------>
<!------------ TODO ------------>
<!-------------------------------
      <material>
        <script>
          <uri>
          <name>
        <shader>
          <normal_map>
        <lighting>
        <ambient>
        <diffuse>
        <specular>
        <emissive>
-------------------------------->
    </visual>
    <inertial>
      <mass>1.183</mass>                                       <!-- Volume = 0.000147 m^3 -->
      <pose>0.0732 -0.0060 -0.0464 0.0000 0.0000 0.0000</pose>
      <inertia>
        <ixx> 0.00518080064</ixx>
        <ixy>-0.00000192063</ixy>
        <ixz>-0.00239985552</ixz>
        <iyy> 0.01473344640</iyy>
        <iyz> 0.00000121663</iyz>
        <izz> 0.00958800384</izz>
      </inertia>
    </inertial>
  </link>

  <link name='Triangle_Rod'>
    <self_collide>0</self_collide>
    <pose>0.0000 -0.4930 0.4320 0.0000 0.0000 0.0000</pose>
    <collision name='Triangle_Rod_Collision'>
      <geometry>
        <mesh>
          <scale>0.0010 0.0010 0.0010</scale>
          <uri>model://msi_rover/meshes/Triangle_Rod.STL</uri>
        </mesh>
      </geometry>
<!------------------------------>
<!------------ TODO ------------>
<!-------------------------------
      <surface>
        <bounce>
          <restitution_coefficient>
-------------------------------->
    </collision>
    <visual name='Triangle_Rod_Visual'>
      <geometry>
        <mesh>
          <scale>0.0010 0.0010 0.0010</scale>
          <uri>model://msi_rover/meshes/Triangle_Rod.STL</uri>
        </mesh>
      </geometry>
<!------------------------------>
<!------------ TODO ------------>
<!-------------------------------
      <material>
        <script>
          <uri>
          <name>
        <shader>
          <normal_map>
        <lighting>
        <ambient>
        <diffuse>
        <specular>
        <emissive>
-------------------------------->
    </visual>
    <inertial>
      <mass>1.183</mass>                                       <!-- Volume = 0.000147 m^3 -->
      <pose>0.0000 -0.0062 0.0000 0.0000 0.0000 0.0000</pose>
      <inertia>
        <ixx> 0.00002827173</ixx>
        <ixy>-0.00000000000</ixy>
        <ixz>-0.00000000000</ixz>
        <iyy> 0.00118691072</iyy>
        <iyz>-0.00000000000</iyz>
        <izz> 0.00116901968</izz>
      </inertia>
    </inertial>
  </link>

  <link name='Left_Diff_Support'>
    <self_collide>0</self_collide>
    <pose>-0.3085 -0.5340 0.5080 -0.4500 0.1500 0.0000</pose>
    <collision name='Left_Diff_Support_Collision'>
      <geometry>
        <cylinder>
          <radius>0.0050</radius>
          <length>0.1700</length>
        </cylinder>
      </geometry>
<!------------------------------>
<!------------ TODO ------------>
<!-------------------------------
      <surface>
        <bounce>
          <restitution_coefficient>
------------------------------->
    </collision>
    <visual name='Left_Diff_Support_Visual'>
      <geometry>
        <cylinder>
          <radius>0.0050</radius>
          <length>0.1700</length>
        </cylinder>
      </geometry>
<!------------------------------>
<!------------ TODO ------------>
<!-------------------------------
      <material>
        <script>
          <uri>
          <name>
        <shader>
          <normal_map>
        <lighting>
        <ambient>
        <diffuse>
        <specular>
        <emissive>
------------------------------->
    </visual>
    <inertial>
      <mass>0.107</mass>                                  <!-- Volume = 0.00001335176 m^3 -->
      <pose>0.0000 0.0000 0.0000 0.0000 0.0000 0.0000</pose>
      <inertia>
        <ixx>0.00025769166</ixx>
        <ixy>0.00000000000</ixy>
        <ixz>0.00000000000</ixz>
        <iyy>0.00025769166</iyy>
        <iyz>0.00000000000</iyz>
        <izz>0.00000133750</izz>
      </inertia>
    </inertial>
  </link>

  <link name='Right_Diff_Support'>
    <self_collide>0</self_collide>
    <pose>0.3085 -0.5340 0.5080 -0.4500 -0.1500 0.0000</pose>
    <collision name='Right_Diff_Support_Collision'>
      <geometry>
        <cylinder>
          <radius>0.0050</radius>
          <length>0.1700</length>
        </cylinder>
      </geometry>
<!------------------------------>
<!------------ TODO ------------>
<!-------------------------------
      <surface>
        <bounce>
          <restitution_coefficient>
------------------------------->
    </collision>
    <visual name='Right_Diff_Support_Visual'>
      <geometry>
        <cylinder>
          <radius>0.0050</radius>
          <length>0.1700</length>
        </cylinder>
      </geometry>
<!------------------------------>
<!------------ TODO ------------>
<!-------------------------------
      <material>
        <script>
          <uri>
          <name>
        <shader>
          <normal_map>
        <lighting>
        <ambient>
        <diffuse>
        <specular>
        <emissive>
------------------------------->
    </visual>
    <inertial>
      <mass>0.107</mass>                                  <!-- Volume = 0.00001335176 m^3 -->
      <pose>0.0000 0.0000 0.0000 0.0000 0.0000 0.0000</pose>
      <inertia>
        <ixx>0.00025769166</ixx>
        <ixy>0.00000000000</ixy>
        <ixz>0.00000000000</ixz>
        <iyy>0.00025769166</iyy>
        <iyz>0.00000000000</iyz>
        <izz>0.00000133750</izz>
      </inertia>
    </inertial>
  </link>

<!------------------------------------------------------------------------------------------>
<!---------------------------         Joints Subsection          --------------------------->
<!------------------------------------------------------------------------------------------>

  <joint type="revolute" name="Right_Triangle_Rod_Joint">
    <pose>0.0750 0.0000 0.0000 0.0000 0.0000 0.0000</pose>
    <child>Triangle_Rod</child>
    <parent>Right_Triangle</parent>
    <axis>
      <xyz>0 1 0</xyz>
<!------------------------------>
<!------------ TODO ------------>
<!-------------------------------
      <dynamics>
        <damping>
        <friction>
      <limit>
        <lower>
        <upper>
        <effort>
        <velocity>
        <stiffness>
        <dissipation>
------------------------------->
    </axis>
<!------------------------------>
<!------------ TODO ------------>
<!-------------------------------
    <physics>
      <ode>
        <provide_feedback>
        <cfm_damping>
        <implicit_spring_damper>
        <fudge_factor>
        <cfm>
        <erp>
        <bounce>
        <max_force>
        <velocity>
        <limit>
          <cfm>
          <erp>
        <suspension>
          <cfm>
          <erp>
------------------------------->
  </joint>

  <joint type="revolute" name="Left_Triangle_Rod_Joint">
    <pose>-0.0750 0.0000 0.0000 0.0000 0.0000 0.0000</pose>
    <child>Triangle_Rod</child>
    <parent>Left_Triangle</parent>
    <axis>
      <xyz>0 1 0</xyz>
<!------------------------------>
<!------------ TODO ------------>
<!-------------------------------
      <dynamics>
        <damping>
        <friction>
      <limit>
        <lower>
        <upper>
        <effort>
        <velocity>
        <stiffness>
        <dissipation>
------------------------------->
    </axis>
<!------------------------------>
<!------------ TODO ------------>
<!-------------------------------
    <physics>
      <ode>
        <provide_feedback>
        <cfm_damping>
        <implicit_spring_damper>
        <fudge_factor>
        <cfm>
        <erp>
        <bounce>
        <max_force>
        <velocity>
        <limit>
          <cfm>
          <erp>
        <suspension>
          <cfm>
          <erp>
------------------------------->
  </joint>

  <joint type="revolute" name="Right_Triangle_Joint">
    <pose>0.0000 0.0000 0.0000 0.0000 0.0000 0.0000</pose>
    <child>Right_Triangle</child>
    <parent>Chassis</parent>
    <axis>
      <xyz>0 1 0</xyz>
<!------------------------------>
<!------------ TODO ------------>
<!-------------------------------
      <dynamics>
        <damping>
        <friction>
      <limit>
        <lower>
        <upper>
        <effort>
        <velocity>
        <stiffness>
        <dissipation>
------------------------------->
    </axis>
<!------------------------------>
<!------------ TODO ------------>
<!-------------------------------
    <physics>
      <ode>
        <provide_feedback>
        <cfm_damping>
        <implicit_spring_damper>
        <fudge_factor>
        <cfm>
        <erp>
        <bounce>
        <max_force>
        <velocity>
        <limit>
          <cfm>
          <erp>
        <suspension>
          <cfm>
          <erp>
------------------------------->
  </joint>

  <joint type="revolute" name="Left_Triangle_Joint">
    <pose>0.0000 0.0000 0.0000 0.0000 0.0000 0.0000</pose>
    <child>Left_Triangle</child>
    <parent>Chassis</parent>
    <axis>
      <xyz>0 1 0</xyz>
<!------------------------------>
<!------------ TODO ------------>
<!-------------------------------
      <dynamics>
        <damping>
        <friction>
      <limit>
        <lower>
        <upper>
        <effort>
        <velocity>
        <stiffness>
        <dissipation>
------------------------------->
    </axis>
<!------------------------------>
<!------------ TODO ------------>
<!-------------------------------
    <physics>
      <ode>
        <provide_feedback>
        <cfm_damping>
        <implicit_spring_damper>
        <fudge_factor>
        <cfm>
        <erp>
        <bounce>
        <max_force>
        <velocity>
        <limit>
          <cfm>
          <erp>
        <suspension>
          <cfm>
          <erp>
------------------------------->
  </joint>

  <joint type="revolute2" name="Left_Diff_Support_Triangle_Joint">
    <pose>0.0000 0.0000 0.0880 0.0000 0.0000 0.0000</pose>
    <child>Left_Diff_Support</child>
    <parent>Left_Triangle</parent>
    <axis>
      <xyz>0 1 0</xyz>
<!------------------------------>
<!------------ TODO ------------>
<!-------------------------------
      <dynamics>
        <damping>
        <friction>
      <limit>
        <lower>
        <upper>
        <effort>
        <velocity>
        <stiffness>
        <dissipation>
------------------------------->
    </axis>
    <axis2>
      <xyz>0 0 1</xyz>
<!------------------------------>
<!------------ TODO ------------>
<!-------------------------------
      <dynamics>
        <damping>
        <friction>
      <limit>
        <lower>
        <upper>
        <effort>
        <velocity>
        <stiffness>
        <dissipation>
------------------------------->
    </axis2>
<!------------------------------>
<!------------ TODO ------------>
<!-------------------------------
    <physics>
      <ode>
        <provide_feedback>
        <cfm_damping>
        <implicit_spring_damper>
        <fudge_factor>
        <cfm>
        <erp>
        <bounce>
        <max_force>
        <velocity>
        <limit>
          <cfm>
          <erp>
        <suspension>
          <cfm>
          <erp>
------------------------------->
  </joint>

  <joint type="revolute2" name="Left_Diff_Support_Rocker_Joint">
    <pose>0.0000 0.0000 -0.0860 0.0000 0.0000 0.0000</pose>
    <child>Left_Diff_Support</child>
    <parent>Left_Rocker</parent>
    <axis>
      <xyz>1 0 0</xyz>
<!------------------------------>
<!------------ TODO ------------>
<!-------------------------------
      <dynamics>
        <damping>
        <friction>
      <limit>
        <lower>
        <upper>
        <effort>
        <velocity>
        <stiffness>
        <dissipation>
------------------------------->
    </axis>
    <axis2>
      <xyz>0 0 1</xyz>
<!------------------------------>
<!------------ TODO ------------>
<!-------------------------------
      <dynamics>
        <damping>
        <friction>
      <limit>
        <lower>
        <upper>
        <effort>
        <velocity>
        <stiffness>
        <dissipation>
------------------------------->
    </axis2>
<!------------------------------>
<!------------ TODO ------------>
<!-------------------------------
    <physics>
      <ode>
        <provide_feedback>
        <cfm_damping>
        <implicit_spring_damper>
        <fudge_factor>
        <cfm>
        <erp>
        <bounce>
        <max_force>
        <velocity>
        <limit>
          <cfm>
          <erp>
        <suspension>
          <cfm>
          <erp>
------------------------------->
  </joint>

  <joint type="revolute2" name="Right_Diff_Support_Triangle_Joint">
    <pose>0.0000 0.0000 0.0880 0.0000 0.0000 0.0000</pose>
    <child>Right_Diff_Support</child>
    <parent>Right_Triangle</parent>
    <axis>
      <xyz>0 1 0</xyz>
<!------------------------------>
<!------------ TODO ------------>
<!-------------------------------
      <dynamics>
        <damping>
        <friction>
      <limit>
        <lower>
        <upper>
        <effort>
        <velocity>
        <stiffness>
        <dissipation>
------------------------------->
    </axis>
    <axis2>
      <xyz>0 0 1</xyz>
<!------------------------------>
<!------------ TODO ------------>
<!-------------------------------
      <dynamics>
        <damping>
        <friction>
      <limit>
        <lower>
        <upper>
        <effort>
        <velocity>
        <stiffness>
        <dissipation>
------------------------------->
    </axis2>
<!------------------------------>
<!------------ TODO ------------>
<!-------------------------------
    <physics>
      <ode>
        <provide_feedback>
        <cfm_damping>
        <implicit_spring_damper>
        <fudge_factor>
        <cfm>
        <erp>
        <bounce>
        <max_force>
        <velocity>
        <limit>
          <cfm>
          <erp>
        <suspension>
          <cfm>
          <erp>
------------------------------->
  </joint>

  <joint type="revolute2" name="Right_Diff_Support_Rocker_Joint">
    <pose>0.0000 0.0000 -0.0860 0.0000 0.0000 0.0000</pose>
    <child>Right_Diff_Support</child>
    <parent>Right_Rocker</parent>
    <axis>
      <xyz>1 0 0</xyz>
<!------------------------------>
<!------------ TODO ------------>
<!-------------------------------
      <dynamics>
        <damping>
        <friction>
      <limit>
        <lower>
        <upper>
        <effort>
        <velocity>
        <stiffness>
        <dissipation>
------------------------------->
    </axis>
    <axis2>
      <xyz>0 0 1</xyz>
<!------------------------------>
<!------------ TODO ------------>
<!-------------------------------
      <dynamics>
        <damping>
        <friction>
      <limit>
        <lower>
        <upper>
        <effort>
        <velocity>
        <stiffness>
        <dissipation>
------------------------------->
    </axis2>
<!------------------------------>
<!------------ TODO ------------>
<!-------------------------------
    <physics>
      <ode>
        <provide_feedback>
        <cfm_damping>
        <implicit_spring_damper>
        <fudge_factor>
        <cfm>
        <erp>
        <bounce>
        <max_force>
        <velocity>
        <limit>
          <cfm>
          <erp>
        <suspension>
          <cfm>
          <erp>
------------------------------->
  </joint>

<!------------------------------------------------------------------------------------------>
<!------------------------------------------------------------------------------------------>
<!---------------------------   Triangle Support Assembly Ends   --------------------------->
<!------------------------------------------------------------------------------------------>
<!------------------------------------------------------------------------------------------>

</model>
</sdf>
