<?xml version='1.0'?>
<sdf version='1.4'>
<model name="MSI Rover">
  <static>0</static>

<!------------------------------------------------------------------------------------------>
<!------------------------------------------------------------------------------------------>
<!---------------------------      Chassis Assembly Begins       --------------------------->
<!------------------------------------------------------------------------------------------>
<!------------------------------------------------------------------------------------------>

  <link name='Chassis'>
    <self_collide>1</self_collide>
    <pose>0.0000 0.0000 0.4720 0.0000 0.0000 0.0000</pose>
    <collision name='Chassis_Collision'>
      <geometry>
        <mesh>
          <scale>0.0010 0.0010 0.0010</scale>
          <uri>model://msi_rover/meshes/Chassis.STL</uri>
        </mesh>
      </geometry>
<!------------------------------>
<!------------ TODO ------------>
<!-------------------------------
      <surface>
        <bounce>
          <restitution_coefficient>
-------------------------------->
    </collision>
    <visual name='Chassis_Visual'>
      <geometry>
        <mesh>
          <scale>0.0010 0.0010 0.0010</scale>
          <uri>model://msi_rover/meshes/Chassis.STL</uri>
        </mesh>
      </geometry>
<!------------------------------>
<!------------ TODO ------------>
<!-------------------------------
      <material>
        <script>
          <uri>
          <name>
        <shader>
          <normal_map>
        <lighting>
        <ambient>
        <diffuse>
        <specular>
        <emissive>
-------------------------------->
    </visual>
    <inertial>
      <mass>7.25940145</mass>                                  <!-- Volume = 0.000902 m^3 -->
      <pose>0.000039 -0.055951 0.001287 0 0 0</pose>
      <inertia>
        <ixx>54.5702500000</ixx>
        <ixy>-0.0031848454</ixy>
        <ixz>-0.001413798</ixz>
        <iyy>55.8663750000</iyy>
        <iyz>2.6596287109</iyz>
        <izz>107.3700250000</izz>
      </inertia>
    </inertial>
  </link>

<!------------------------------------------------------------------------------------------>
<!------------------------------------------------------------------------------------------>
<!---------------------------       Chassis Assembly Ends        --------------------------->
<!------------------------------------------------------------------------------------------>
<!------------------------------------------------------------------------------------------>
<!--------------------------- Left Rocker-Bogie Assembly Begins  --------------------------->
<!------------------------------------------------------------------------------------------>
<!------------------------------------------------------------------------------------------>

  <link name='Left_Rocker'>
    <self_collide>1</self_collide>
    <pose>-0.3270 0.0000 0.4720 0.0000 0.0000 0.0000</pose>
    <collision name='Left_Rocker_Collision'>
      <geometry>
        <mesh>
          <scale>0.0010 0.0010 0.0010</scale>
          <uri>model://msi_rover/meshes/Rocker_L.STL</uri>
        </mesh>
      </geometry>
<!------------------------------>
<!------------ TODO ------------>
<!-------------------------------
      <surface>
        <bounce>
          <restitution_coefficient>
-------------------------------->
    </collision>
    <visual name='Left_Rocker_Visual'>
      <geometry>
        <mesh>
          <scale>0.0010 0.0010 0.0010</scale>
          <uri>model://msi_rover/meshes/Rocker_L.STL</uri>
        </mesh>
      </geometry>
<!------------------------------>
<!------------ TODO ------------>
<!-------------------------------
      <material>
        <script>
          <uri>
          <name>
        <shader>
          <normal_map>
        <lighting>
        <ambient>
        <diffuse>
        <specular>
        <emissive>
-------------------------------->
    </visual>
<!------------------------------>
<!------------ TODO ------------>
<!-------------------------------
    <inertial>
      <mass>
      <pose>
      <inertia>
        <ixx>
        <ixy>
        <ixz>
        <iyy>
        <iyz>
        <izz>
-------------------------------->
  </link>

  <link name='Left_Bogie'>
    <self_collide>1</self_collide>
    <pose>-0.2940 0.1750 0.4320 0.0000 0.0000 0.0000</pose>
    <collision name='Left_Bogie_Collision'>
      <geometry>
        <mesh>
          <scale>0.0010 0.0010 0.0010</scale>
          <uri>model://msi_rover/meshes/Bogie_L.STL</uri>
        </mesh>
      </geometry>
<!------------------------------>
<!------------ TODO ------------>
<!-------------------------------
      <surface>
        <bounce>
          <restitution_coefficient>
-------------------------------->
    </collision>
    <visual name='Left_Bogie_Visual'>
      <geometry>
        <mesh>
          <scale>0.0010 0.0010 0.0010</scale>
          <uri>model://msi_rover/meshes/Bogie_L.STL</uri>
        </mesh>
      </geometry>
<!------------------------------>
<!------------ TODO ------------>
<!-------------------------------
      <material>
        <script>
          <uri>
          <name>
        <shader>
          <normal_map>
        <lighting>
        <ambient>
        <diffuse>
        <specular>
        <emissive>
-------------------------------->
    </visual>
<!------------------------------>
<!------------ TODO ------------>
<!-------------------------------
    <inertial>
      <mass>
      <pose>
      <inertia>
        <ixx>
        <ixy>
        <ixz>
        <iyy>
        <iyz>
        <izz>
-------------------------------->
  </link>

  <link name='Left_Rear_Steering'>
    <self_collide>1</self_collide>
    <pose>-0.3810 -0.4900 0.36800 0.0000 0.0000 0.0000</pose>
    <collision name='Left_Rear_Steering_Collision'>
      <geometry>
        <mesh>
          <scale>0.0010 0.0010 0.0010</scale>
          <uri>model://msi_rover/meshes/C_Assembly_L.STL</uri>
        </mesh>
      </geometry>
<!------------------------------>
<!------------ TODO ------------>
<!-------------------------------
      <surface>
        <bounce>
          <restitution_coefficient>
-------------------------------->
    </collision>
    <visual name='Left_Rear_Steering_Visual'>
      <geometry>
        <mesh>
          <scale>0.0010 0.0010 0.0010</scale>
          <uri>model://msi_rover/meshes/C_Assembly_L.STL</uri>
        </mesh>
      </geometry>
<!------------------------------>
<!------------ TODO ------------>
<!-------------------------------
      <material>
        <script>
          <uri>
          <name>
        <shader>
          <normal_map>
        <lighting>
        <ambient>
        <diffuse>
        <specular>
        <emissive>
-------------------------------->
    </visual>
<!------------------------------>
<!------------ TODO ------------>
<!-------------------------------
    <inertial>
      <mass>
      <pose>
      <inertia>
        <ixx>
        <ixy>
        <ixz>
        <iyy>
        <iyz>
        <izz>
-------------------------------->
  </link>

  <link name='Left_Front_Steering'>
    <self_collide>1</self_collide>
    <pose>-0.3480 0.4000 0.3680 0.0000 0.0000 0.0000</pose>
    <collision name='Left_Front_Steering_Collision'>
      <geometry>
        <mesh>
          <scale>0.0010 0.0010 0.0010</scale>
          <uri>model://msi_rover/meshes/C_Assembly_L.STL</uri>
        </mesh>
      </geometry>
<!------------------------------>
<!------------ TODO ------------>
<!-------------------------------
      <surface>
        <bounce>
          <restitution_coefficient>
-------------------------------->
    </collision>
    <visual name='Left_Front_Steering_Visual'>
      <geometry>
        <mesh>
          <scale>0.0010 0.0010 0.0010</scale>
          <uri>model://msi_rover/meshes/C_Assembly_L.STL</uri>
        </mesh>
      </geometry>
<!------------------------------>
<!------------ TODO ------------>
<!-------------------------------
      <material>
        <script>
          <uri>
          <name>
        <shader>
          <normal_map>
        <lighting>
        <ambient>
        <diffuse>
        <specular>
        <emissive>
-------------------------------->
    </visual>
<!------------------------------>
<!------------ TODO ------------>
<!-------------------------------
    <inertial>
      <mass>
      <pose>
      <inertia>
        <ixx>
        <ixy>
        <ixz>
        <iyy>
        <iyz>
        <izz>
------------------------------->
  </link>

  <link name='Left_Rear_Tyre'>
    <self_collide>1</self_collide>
    <pose>-0.3910 -0.4900 0.1500 0.0000 0.0000 0.0000</pose>
    <collision name='Left_Rear_Tyre_Collision'>
      <geometry>
        <mesh>
          <scale>0.0010 0.0010 0.0010</scale>
          <uri>model://msi_rover/meshes/Tyre.STL</uri>
        </mesh>
      </geometry>
<!------------------------------>
<!------------ TODO ------------>
<!-------------------------------
      <surface>
        <bounce>
          <restitution_coefficient>
-------------------------------->
    </collision>
    <visual name='Left_Rear_Tyre_Visual'>
      <geometry>
        <mesh>
          <scale>0.0010 0.0010 0.0010</scale>
          <uri>model://msi_rover/meshes/Tyre.STL</uri>
        </mesh>
      </geometry>
<!------------------------------>
<!------------ TODO ------------>
<!-------------------------------
      <material>
        <script>
          <uri>
          <name>
        <shader>
          <normal_map>
        <lighting>
        <ambient>
        <diffuse>
        <specular>
        <emissive>
-------------------------------->
    </visual>
<!------------------------------>
<!------------ TODO ------------>
<!-------------------------------
    <inertial>
      <mass>
      <pose>
      <inertia>
        <ixx>
        <ixy>
        <ixz>
        <iyy>
        <iyz>
        <izz>
------------------------------->
  </link>

  <link name='Left_Middle_Tyre'>
    <self_collide>1</self_collide>
    <pose>-0.4480 -0.0500 0.1500 0.0000 0.0000 0.0000</pose>
    <collision name='Left_Middle_Tyre_Collision'>
      <geometry>
        <mesh>
          <scale>0.0010 0.0010 0.0010</scale>
          <uri>model://msi_rover/meshes/Tyre.STL</uri>
        </mesh>
      </geometry>
<!------------------------------>
<!------------ TODO ------------>
<!-------------------------------
      <surface>
        <bounce>
          <restitution_coefficient>
------------------------------->
    </collision>
    <visual name='Left_Middle_Tyre_Visual'>
      <geometry>
        <mesh>
          <scale>0.0010 0.0010 0.0010</scale>
          <uri>model://msi_rover/meshes/Tyre.STL</uri>
        </mesh>
      </geometry>
<!------------------------------>
<!------------ TODO ------------>
<!-------------------------------
      <material>
        <script>
          <uri>
          <name>
        <shader>
          <normal_map>
        <lighting>
        <ambient>
        <diffuse>
        <specular>
        <emissive>
------------------------------->
    </visual>
<!------------------------------>
<!------------ TODO ------------>
<!-------------------------------
    <inertial>
      <mass>
      <pose>
      <inertia>
        <ixx>
        <ixy>
        <ixz>
        <iyy>
        <iyz>
        <izz>
------------------------------->
  </link>

  <link name='Left_Front_Tyre'>
    <self_collide>1</self_collide>
    <pose>-0.3580 0.4000 0.1500 0.0000 0.0000 0.0000</pose>
    <collision name='Left_Front_Tyre_Collision'>
      <geometry>
        <mesh>
          <scale>0.0010 0.0010 0.0010</scale>
          <uri>model://msi_rover/meshes/Tyre.STL</uri>
        </mesh>
      </geometry>
<!------------------------------>
<!------------ TODO ------------>
<!-------------------------------
      <surface>
        <bounce>
          <restitution_coefficient>
------------------------------->
    </collision>
    <visual name='Left_Front_Tyre_Visual'>
      <geometry>
        <mesh>
          <scale>0.0010 0.0010 0.0010</scale>
          <uri>model://msi_rover/meshes/Tyre.STL</uri>
        </mesh>
      </geometry>
<!------------------------------>
<!------------ TODO ------------>
<!-------------------------------
      <material>
        <script>
          <uri>
          <name>
        <shader>
          <normal_map>
        <lighting>
        <ambient>
        <diffuse>
        <specular>
        <emissive>
------------------------------->
    </visual>
<!------------------------------>
<!------------ TODO ------------>
<!-------------------------------
    <inertial>
      <mass>
      <pose>
      <inertia>
        <ixx>
        <ixy>
        <ixz>
        <iyy>
        <iyz>
        <izz>
------------------------------->
  </link>

<!------------------------------------------------------------------------------------------>
<!---------------------------         Joints Subsection          --------------------------->
<!------------------------------------------------------------------------------------------>

  <joint type="revolute" name="Left_Rocker_Joint">
    <pose>0.0000 0.0000 0.0000 0.0000 0.0000 0.0000</pose>
    <child>Left_Rocker</child>
    <parent>Chassis</parent>
    <axis>
      <xyz>1 0 0</xyz>
<!------------------------------>
<!------------ TODO ------------>
<!-------------------------------
      <dynamics>
        <damping>
        <friction>
      <limit>
        <lower>
        <upper>
        <effort>
        <velocity>
        <stiffness>
        <dissipation>
------------------------------->
    </axis>
<!------------------------------>
<!------------ TODO ------------>
<!-------------------------------
    <physics>
      <ode>
        <provide_feedback>
        <cfm_damping>
        <implicit_spring_damper>
        <fudge_factor>
        <cfm>
        <erp>
        <bounce>
        <max_force>
        <velocity>
        <limit>
          <cfm>
          <erp>
        <suspension>
          <cfm>
          <erp>
------------------------------->
  </joint>

  <joint type="revolute" name="Left_Bogie_Joint">
    <pose>0.0000 0.0000 0.0000 0.0000 0.0000 0.0000</pose>
    <child>Left_Bogie</child>
    <parent>Left_Rocker</parent>
    <axis>
      <xyz>1 0 0</xyz>
<!------------------------------>
<!------------ TODO ------------>
<!-------------------------------
      <dynamics>
        <damping>
        <friction>
      <limit>
        <lower>
        <upper>
        <effort>
        <velocity>
        <stiffness>
        <dissipation>
------------------------------->
    </axis>
<!------------------------------>
<!------------ TODO ------------>
<!-------------------------------
    <physics>
      <ode>
        <provide_feedback>
        <cfm_damping>
        <implicit_spring_damper>
        <fudge_factor>
        <cfm>
        <erp>
        <bounce>
        <max_force>
        <velocity>
        <limit>
          <cfm>
          <erp>
        <suspension>
          <cfm>
          <erp>
------------------------------->
  </joint>

  <joint type="revolute" name="Left_Rear_Steering_Joint">
    <pose>0.0000 0.0000 0.0000 0.0000 0.0000 0.0000</pose>
    <child>Left_Rear_Steering</child>
    <parent>Left_Rocker</parent>
    <axis>
      <xyz>0 0 -1</xyz>
<!------------------------------>
<!------------ TODO ------------>
<!------------------------------>
      <limit>
        <lower>0</lower>
        <upper>0</upper>
      </limit>
<!------------------------------>
<!------------ TODO ------------>
<!-------------------------------
      <dynamics>
        <damping>
        <friction>
      <limit>
        <lower>
        <upper>
        <effort>
        <velocity>
        <stiffness>
        <dissipation>
------------------------------->
    </axis>
<!------------------------------>
<!------------ TODO ------------>
<!-------------------------------
    <physics>
      <ode>
        <provide_feedback>
        <cfm_damping>
        <implicit_spring_damper>
        <fudge_factor>
        <cfm>
        <erp>
        <bounce>
        <max_force>
        <velocity>
        <limit>
          <cfm>
          <erp>
        <suspension>
          <cfm>
          <erp>
------------------------------->
  </joint>

  <joint type="revolute" name="Left_Front_Steering_Joint">
    <pose>0.0000 0.0000 0.0000 0.0000 0.0000 0.0000</pose>
    <child>Left_Front_Steering</child>
    <parent>Left_Bogie</parent>
    <axis>
      <xyz>0 0 -1</xyz>
<!------------------------------>
<!------------ TODO ------------>
<!------------------------------>
      <limit>
        <lower>0</lower>
        <upper>0</upper>
      </limit>
<!------------------------------>
<!------------ TODO ------------>
<!-------------------------------
      <dynamics>
        <damping>
        <friction>
      <limit>
        <lower>
        <upper>
        <effort>
        <velocity>
        <stiffness>
        <dissipation>
------------------------------->
    </axis>
<!------------------------------>
<!------------ TODO ------------>
<!-------------------------------
    <physics>
      <ode>
        <provide_feedback>
        <cfm_damping>
        <implicit_spring_damper>
        <fudge_factor>
        <cfm>
        <erp>
        <bounce>
        <max_force>
        <velocity>
        <limit>
          <cfm>
          <erp>
        <suspension>
          <cfm>
          <erp>
------------------------------->
  </joint>

  <joint type="revolute" name="Left_Rear_Tyre_Joint">
    <pose>0.0000 0.0000 0.0000 0.0000 0.0000 0.0000</pose>
    <child>Left_Rear_Tyre</child>
    <parent>Left_Rear_Steering</parent>
    <axis>
      <xyz>1 0 0</xyz>
<!------------------------------>
<!------------ TODO ------------>
<!-------------------------------
      <dynamics>
        <damping>
        <friction>
      <limit>
        <lower>
        <upper>
        <effort>
        <velocity>
        <stiffness>
        <dissipation>
------------------------------->
    </axis>
<!------------------------------>
<!------------ TODO ------------>
<!-------------------------------
    <physics>
      <ode>
        <provide_feedback>
        <cfm_damping>
        <implicit_spring_damper>
        <fudge_factor>
        <cfm>
        <erp>
        <bounce>
        <max_force>
        <velocity>
        <limit>
          <cfm>
          <erp>
        <suspension>
          <cfm>
          <erp>
------------------------------->
  </joint>

  <joint type="revolute" name="Left_Middle_Tyre_Joint">
    <pose>0.0000 0.0000 0.0000 0.0000 0.0000 0.0000</pose>
    <child>Left_Middle_Tyre</child>
    <parent>Left_Bogie</parent>
    <axis>
      <xyz>1 0 0</xyz>
<!------------------------------>
<!------------ TODO ------------>
<!-------------------------------
      <dynamics>
        <damping>
        <friction>
      <limit>
        <lower>
        <upper>
        <effort>
        <velocity>
        <stiffness>
        <dissipation>
------------------------------->
    </axis>
<!------------------------------>
<!------------ TODO ------------>
<!-------------------------------
    <physics>
      <ode>
        <provide_feedback>
        <cfm_damping>
        <implicit_spring_damper>
        <fudge_factor>
        <cfm>
        <erp>
        <bounce>
        <max_force>
        <velocity>
        <limit>
          <cfm>
          <erp>
        <suspension>
          <cfm>
          <erp>
------------------------------->
  </joint>

  <joint type="revolute" name="Left_Front_Tyre_Joint">
    <pose>0.0000 0.0000 0.0000 0.0000 0.0000 0.0000</pose>
    <child>Left_Front_Tyre</child>
    <parent>Left_Front_Steering</parent>
    <axis>
      <xyz>1 0 0</xyz>
<!------------------------------>
<!------------ TODO ------------>
<!-------------------------------
      <dynamics>
        <damping>
        <friction>
      <limit>
        <lower>
        <upper>
        <effort>
        <velocity>
        <stiffness>
        <dissipation>
------------------------------->
    </axis>
<!------------------------------>
<!------------ TODO ------------>
<!-------------------------------
    <physics>
      <ode>
        <provide_feedback>
        <cfm_damping>
        <implicit_spring_damper>
        <fudge_factor>
        <cfm>
        <erp>
        <bounce>
        <max_force>
        <velocity>
        <limit>
          <cfm>
          <erp>
        <suspension>
          <cfm>
          <erp>
------------------------------->
  </joint>

<!------------------------------------------------------------------------------------------>
<!------------------------------------------------------------------------------------------>
<!---------------------------  Left Rocker-Bogie Assembly Ends   --------------------------->
<!------------------------------------------------------------------------------------------>
<!------------------------------------------------------------------------------------------>
<!--------------------------- Right Rocker-Bogie Assembly Begins --------------------------->
<!------------------------------------------------------------------------------------------>
<!------------------------------------------------------------------------------------------>

  <link name='Right_Rocker'>
    <self_collide>1</self_collide>
    <pose>0.3270 0.0000 0.4720 0.0000 0.0000 0.0000</pose>
    <collision name='Right_Rocker_Collision'>
      <geometry>
        <mesh>
          <scale>0.0010 0.0010 0.0010</scale>
          <uri>model://msi_rover/meshes/Rocker_R.STL</uri>
        </mesh>
      </geometry>
<!------------------------------>
<!------------ TODO ------------>
<!-------------------------------
      <surface>
        <bounce>
          <restitution_coefficient>
------------------------------->
    </collision>
    <visual name='Right_Rocker_Visual'>
      <geometry>
        <mesh>
          <scale>0.0010 0.0010 0.0010</scale>
          <uri>model://msi_rover/meshes/Rocker_R.STL</uri>
        </mesh>
      </geometry>
<!------------------------------>
<!------------ TODO ------------>
<!-------------------------------
      <material>
        <script>
          <uri>
          <name>
        <shader>
          <normal_map>
        <lighting>
        <ambient>
        <diffuse>
        <specular>
        <emissive>
------------------------------->
    </visual>
<!------------------------------>
<!------------ TODO ------------>
<!-------------------------------
    <inertial>
      <mass>
      <pose>
      <inertia>
        <ixx>
        <ixy>
        <ixz>
        <iyy>
        <iyz>
        <izz>
------------------------------->
  </link>

  <link name='Right_Bogie'>
    <self_collide>1</self_collide>
    <pose>0.2940 0.1750 0.4320 0.0000 0.0000 0.0000</pose>
    <collision name='Right_Bogie_Collision'>
      <geometry>
        <mesh>
          <scale>0.0010 0.0010 0.0010</scale>
          <uri>model://msi_rover/meshes/Bogie_R.STL</uri>
        </mesh>
      </geometry>
<!------------------------------>
<!------------ TODO ------------>
<!-------------------------------
      <surface>
        <bounce>
          <restitution_coefficient>
------------------------------->
    </collision>
    <visual name='Right_Bogie_Visual'>
      <geometry>
        <mesh>
          <scale>0.0010 0.0010 0.0010</scale>
          <uri>model://msi_rover/meshes/Bogie_R.STL</uri>
        </mesh>
      </geometry>
<!------------------------------>
<!------------ TODO ------------>
<!-------------------------------
      <material>
        <script>
          <uri>
          <name>
        <shader>
          <normal_map>
        <lighting>
        <ambient>
        <diffuse>
        <specular>
        <emissive>
------------------------------->
    </visual>
<!------------------------------>
<!------------ TODO ------------>
<!-------------------------------
    <inertial>
      <mass>
      <pose>
      <inertia>
        <ixx>
        <ixy>
        <ixz>
        <iyy>
        <iyz>
        <izz>
------------------------------->
  </link>

  <link name='Right_Rear_Steering'>
    <self_collide>1</self_collide>
    <pose>0.3810 -0.4900 0.3680 0.0000 0.0000 0.0000</pose>
    <collision name='Right_Rear_Steering_Collision'>
      <geometry>
        <mesh>
          <scale>0.0010 0.0010 0.0010</scale>
          <uri>model://msi_rover/meshes/C_Assembly_R.STL</uri>
        </mesh>
      </geometry>
<!------------------------------>
<!------------ TODO ------------>
<!-------------------------------
      <surface>
        <bounce>
          <restitution_coefficient>
------------------------------->
    </collision>
    <visual name='Right_Rear_Steering_Visual'>
      <geometry>
        <mesh>
          <scale>0.0010 0.0010 0.0010</scale>
          <uri>model://msi_rover/meshes/C_Assembly_R.STL</uri>
        </mesh>
      </geometry>
<!------------------------------>
<!------------ TODO ------------>
<!-------------------------------
      <material>
        <script>
          <uri>
          <name>
        <shader>
          <normal_map>
        <lighting>
        <ambient>
        <diffuse>
        <specular>
        <emissive>
------------------------------->
    </visual>
<!------------------------------>
<!------------ TODO ------------>
<!-------------------------------
    <inertial>
      <mass>
      <pose>
      <inertia>
        <ixx>
        <ixy>
        <ixz>
        <iyy>
        <iyz>
        <izz>
------------------------------->
  </link>

  <link name='Right_Front_Steering'>
    <self_collide>1</self_collide>
    <pose>0.3480 0.4000 0.3680 0.0000 0.0000 0.0000</pose>
    <collision name='Right_Front_Steering_Collision'>
      <geometry>
        <mesh>
          <scale>0.0010 0.0010 0.0010</scale>
          <uri>model://msi_rover/meshes/C_Assembly_R.STL</uri>
        </mesh>
      </geometry>
<!------------------------------>
<!------------ TODO ------------>
<!-------------------------------
      <surface>
        <bounce>
          <restitution_coefficient>
------------------------------->
    </collision>
    <visual name='Right_Front_Steering_Visual'>
      <geometry>
        <mesh>
          <scale>0.0010 0.0010 0.0010</scale>
          <uri>model://msi_rover/meshes/C_Assembly_R.STL</uri>
        </mesh>
      </geometry>
<!------------------------------>
<!------------ TODO ------------>
<!-------------------------------
      <material>
        <script>
          <uri>
          <name>
        <shader>
          <normal_map>
        <lighting>
        <ambient>
        <diffuse>
        <specular>
        <emissive>
------------------------------->
    </visual>
<!------------------------------>
<!------------ TODO ------------>
<!-------------------------------
    <inertial>
      <mass>
      <pose>
      <inertia>
        <ixx>
        <ixy>
        <ixz>
        <iyy>
        <iyz>
        <izz>
------------------------------->
  </link>

  <link name='Right_Rear_Tyre'>
    <self_collide>1</self_collide>
    <pose>0.3910 -0.4900 0.1500 0.0000 0.0000 0.0000</pose>
    <collision name='Right_Rear_Tyre_Collision'>
      <geometry>
        <mesh>
          <scale>0.0010 0.0010 0.0010</scale>
          <uri>model://msi_rover/meshes/Tyre.STL</uri>
        </mesh>
      </geometry>
<!------------------------------>
<!------------ TODO ------------>
<!-------------------------------
      <surface>
        <bounce>
          <restitution_coefficient>
------------------------------->
    </collision>
    <visual name='Right_Rear_Tyre_Visual'>
      <geometry>
        <mesh>
          <scale>0.0010 0.0010 0.0010</scale>
          <uri>model://msi_rover/meshes/Tyre.STL</uri>
        </mesh>
      </geometry>
<!------------------------------>
<!------------ TODO ------------>
<!-------------------------------
      <material>
        <script>
          <uri>
          <name>
        <shader>
          <normal_map>
        <lighting>
        <ambient>
        <diffuse>
        <specular>
        <emissive>
------------------------------->
    </visual>
<!------------------------------>
<!------------ TODO ------------>
<!-------------------------------
    <inertial>
      <mass>
      <pose>
      <inertia>
        <ixx>
        <ixy>
        <ixz>
        <iyy>
        <iyz>
        <izz>
------------------------------->
  </link>

  <link name='Right_Middle_Tyre'>
    <self_collide>1</self_collide>
    <pose>0.4480 -0.0500 0.1500 0.0000 0.0000 0.0000</pose>
    <collision name='Right_Middle_Tyre_Collision'>
      <geometry>
        <mesh>
          <scale>0.0010 0.0010 0.0010</scale>
          <uri>model://msi_rover/meshes/Tyre.STL</uri>
        </mesh>
      </geometry>
<!------------------------------>
<!------------ TODO ------------>
<!-------------------------------
      <surface>
        <bounce>
          <restitution_coefficient>
------------------------------->
    </collision>
    <visual name='Right_Middle_Tyre_Visual'>
      <geometry>
        <mesh>
          <scale>0.0010 0.0010 0.0010</scale>
          <uri>model://msi_rover/meshes/Tyre.STL</uri>
        </mesh>
      </geometry>
<!------------------------------>
<!------------ TODO ------------>
<!-------------------------------
      <material>
        <script>
          <uri>
          <name>
        <shader>
          <normal_map>
        <lighting>
        <ambient>
        <diffuse>
        <specular>
        <emissive>
------------------------------->
    </visual>
<!------------------------------>
<!------------ TODO ------------>
<!-------------------------------
    <inertial>
      <mass>
      <pose>
      <inertia>
        <ixx>
        <ixy>
        <ixz>
        <iyy>
        <iyz>
        <izz>
------------------------------->
  </link>

  <link name='Right_Front_Tyre'>
    <self_collide>1</self_collide>
    <pose>0.3580 0.4000 0.1500 0.0000 0.0000 0.0000</pose>
    <collision name='Right_Front_Tyre_Collision'>
      <geometry>
        <mesh>
          <scale>0.0010 0.0010 0.0010</scale>
          <uri>model://msi_rover/meshes/Tyre.STL</uri>
        </mesh>
      </geometry>
<!------------------------------>
<!------------ TODO ------------>
<!-------------------------------
      <surface>
        <bounce>
          <restitution_coefficient>
------------------------------->
    </collision>
    <visual name='Right_Front_Tyre_Visual'>
      <geometry>
        <mesh>
          <scale>0.0010 0.0010 0.0010</scale>
          <uri>model://msi_rover/meshes/Tyre.STL</uri>
        </mesh>
      </geometry>
<!------------------------------>
<!------------ TODO ------------>
<!-------------------------------
      <material>
        <script>
          <uri>
          <name>
        <shader>
          <normal_map>
        <lighting>
        <ambient>
        <diffuse>
        <specular>
        <emissive>
------------------------------->
    </visual>
<!------------------------------>
<!------------ TODO ------------>
<!-------------------------------
    <inertial>
      <mass>
      <pose>
      <inertia>
        <ixx>
        <ixy>
        <ixz>
        <iyy>
        <iyz>
        <izz>
------------------------------->
  </link>

<!------------------------------------------------------------------------------------------>
<!---------------------------         Joints Subsection          --------------------------->
<!------------------------------------------------------------------------------------------>

  <joint type="revolute" name="Right_Rocker_Joint">
    <pose>0.0000 0.0000 0.0000 0.0000 0.0000 0.0000</pose>
    <child>Right_Rocker</child>
    <parent>Chassis</parent>
    <axis>
      <xyz>1 0 0</xyz>
<!------------------------------>
<!------------ TODO ------------>
<!-------------------------------
      <dynamics>
        <damping>
        <friction>
      <limit>
        <lower>
        <upper>
        <effort>
        <velocity>
        <stiffness>
        <dissipation>
------------------------------->
    </axis>
<!------------------------------>
<!------------ TODO ------------>
<!-------------------------------
    <physics>
      <ode>
        <provide_feedback>
        <cfm_damping>
        <implicit_spring_damper>
        <fudge_factor>
        <cfm>
        <erp>
        <bounce>
        <max_force>
        <velocity>
        <limit>
          <cfm>
          <erp>
        <suspension>
          <cfm>
          <erp>
------------------------------->
  </joint>

  <joint type="revolute" name="Right_Bogie_Joint">
    <pose>0.0000 0.0000 0.0000 0.0000 0.0000 0.0000</pose>
    <child>Right_Bogie</child>
    <parent>Right_Rocker</parent>
    <axis>
      <xyz>1 0 0</xyz>
<!------------------------------>
<!------------ TODO ------------>
<!-------------------------------
      <dynamics>
        <damping>
        <friction>
      <limit>
        <lower>
        <upper>
        <effort>
        <velocity>
        <stiffness>
        <dissipation>
------------------------------->
    </axis>
<!------------------------------>
<!------------ TODO ------------>
<!-------------------------------
    <physics>
      <ode>
        <provide_feedback>
        <cfm_damping>
        <implicit_spring_damper>
        <fudge_factor>
        <cfm>
        <erp>
        <bounce>
        <max_force>
        <velocity>
        <limit>
          <cfm>
          <erp>
        <suspension>
          <cfm>
          <erp>
------------------------------->
  </joint>

  <joint type="revolute" name="Right_Rear_Steering_Joint">
    <pose>0.0000 0.0000 0.0000 0.0000 0.0000 0.0000</pose>
    <child>Right_Rear_Steering</child>
    <parent>Right_Rocker</parent>
    <axis>
      <xyz>0 0 -1</xyz>
<!------------------------------>
<!------------ TODO ------------>
<!------------------------------>
      <limit>
        <lower>0</lower>
        <upper>0</upper>
      </limit>
<!------------------------------>
<!------------ TODO ------------>
<!-------------------------------
      <dynamics>
        <damping>
        <friction>
      <limit>
        <lower>
        <upper>
        <effort>
        <velocity>
        <stiffness>
        <dissipation>
------------------------------->
    </axis>
<!------------------------------>
<!------------ TODO ------------>
<!-------------------------------
    <physics>
      <ode>
        <provide_feedback>
        <cfm_damping>
        <implicit_spring_damper>
        <fudge_factor>
        <cfm>
        <erp>
        <bounce>
        <max_force>
        <velocity>
        <limit>
          <cfm>
          <erp>
        <suspension>
          <cfm>
          <erp>
------------------------------->
  </joint>

  <joint type="revolute" name="Right_Front_Steering_Joint">
    <pose>0.0000 0.0000 0.0000 0.0000 0.0000 0.0000</pose>
    <child>Right_Front_Steering</child>
    <parent>Right_Bogie</parent>
    <axis>
      <xyz>0 0 -1</xyz>
<!------------------------------>
<!------------ TODO ------------>
<!------------------------------>
      <limit>
        <lower>0</lower>
        <upper>0</upper>
      </limit>
<!------------------------------>
<!------------ TODO ------------>
<!-------------------------------
      <dynamics>
        <damping>
        <friction>
      <limit>
        <lower>
        <upper>
        <effort>
        <velocity>
        <stiffness>
        <dissipation>
------------------------------->
    </axis>
<!------------------------------>
<!------------ TODO ------------>
<!-------------------------------
    <physics>
      <ode>
        <provide_feedback>
        <cfm_damping>
        <implicit_spring_damper>
        <fudge_factor>
        <cfm>
        <erp>
        <bounce>
        <max_force>
        <velocity>
        <limit>
          <cfm>
          <erp>
        <suspension>
          <cfm>
          <erp>
------------------------------->
  </joint>

  <joint type="revolute" name="Right_Rear_Tyre_Joint">
    <pose>0.0000 0.0000 0.0000 0.0000 0.0000 0.0000</pose>
    <child>Right_Rear_Tyre</child>
    <parent>Right_Rear_Steering</parent>
    <axis>
      <xyz>1 0 0</xyz>
<!------------------------------>
<!------------ TODO ------------>
<!-------------------------------
      <dynamics>
        <damping>
        <friction>
      <limit>
        <lower>
        <upper>
        <effort>
        <velocity>
        <stiffness>
        <dissipation>
------------------------------->
    </axis>
<!------------------------------>
<!------------ TODO ------------>
<!-------------------------------
    <physics>
      <ode>
        <provide_feedback>
        <cfm_damping>
        <implicit_spring_damper>
        <fudge_factor>
        <cfm>
        <erp>
        <bounce>
        <max_force>
        <velocity>
        <limit>
          <cfm>
          <erp>
        <suspension>
          <cfm>
          <erp>
------------------------------->
  </joint>

  <joint type="revolute" name="Right_Middle_Tyre_Joint">
    <pose>0.0000 0.0000 0.0000 0.0000 0.0000 0.0000</pose>
    <child>Right_Middle_Tyre</child>
    <parent>Right_Bogie</parent>
    <axis>
      <xyz>1 0 0</xyz>
<!------------------------------>
<!------------ TODO ------------>
<!-------------------------------
      <dynamics>
        <damping>
        <friction>
      <limit>
        <lower>
        <upper>
        <effort>
        <velocity>
        <stiffness>
        <dissipation>
------------------------------->
    </axis>
<!------------------------------>
<!------------ TODO ------------>
<!-------------------------------
    <physics>
      <ode>
        <provide_feedback>
        <cfm_damping>
        <implicit_spring_damper>
        <fudge_factor>
        <cfm>
        <erp>
        <bounce>
        <max_force>
        <velocity>
        <limit>
          <cfm>
          <erp>
        <suspension>
          <cfm>
          <erp>
------------------------------->
  </joint>

  <joint type="revolute" name="Right_Front_Tyre_Joint">
    <pose>0.0000 0.0000 0.0000 0.0000 0.0000 0.0000</pose>
    <child>Right_Front_Tyre</child>
    <parent>Right_Front_Steering</parent>
    <axis>
      <xyz>1 0 0</xyz>
<!------------------------------>
<!------------ TODO ------------>
<!-------------------------------
      <dynamics>
        <damping>
        <friction>
      <limit>
        <lower>
        <upper>
        <effort>
        <velocity>
        <stiffness>
        <dissipation>
------------------------------->
    </axis>
<!------------------------------>
<!------------ TODO ------------>
<!-------------------------------
    <physics>
      <ode>
        <provide_feedback>
        <cfm_damping>
        <implicit_spring_damper>
        <fudge_factor>
        <cfm>
        <erp>
        <bounce>
        <max_force>
        <velocity>
        <limit>
          <cfm>
          <erp>
        <suspension>
          <cfm>
          <erp>
------------------------------->
  </joint>

<!------------------------------------------------------------------------------------------>
<!------------------------------------------------------------------------------------------>
<!---------------------------  Right Rocker-Bogie Assembly Ends  --------------------------->
<!------------------------------------------------------------------------------------------>
<!------------------------------------------------------------------------------------------>
<!---------------------------  Triangle Support Assembly Begins  --------------------------->
<!------------------------------------------------------------------------------------------>
<!------------------------------------------------------------------------------------------>
<!------------------------  TODO: REPAIR AND COMPLETE THIS ASSEMBLY ------------------------>
<!------------------------------------------------------------------------------------------>
<!------------------------------------------------------------------------------------------>

  <link name='Left_Triangle'>
    <self_collide>1</self_collide>
    <pose>-0.0720 -0.4800 0.5820 0.0000 0.0000 0.0000</pose>
    <collision name='Left_Triangle_Collision'>
      <geometry>
        <mesh>
          <scale>0.0010 0.0010 0.0010</scale>
          <uri>model://msi_rover/meshes/Triangle_L.STL</uri>
        </mesh>
      </geometry>
<!------------------------------>
<!------------ TODO ------------>
<!-------------------------------
      <surface>
        <bounce>
          <restitution_coefficient>
-------------------------------->
    </collision>
    <visual name='Left_Triangle_Visual'>
      <geometry>
        <mesh>
          <scale>0.0010 0.0010 0.0010</scale>
          <uri>model://msi_rover/meshes/Triangle_L.STL</uri>
        </mesh>
      </geometry>
<!------------------------------>
<!------------ TODO ------------>
<!-------------------------------
      <material>
        <script>
          <uri>
          <name>
        <shader>
          <normal_map>
        <lighting>
        <ambient>
        <diffuse>
        <specular>
        <emissive>
-------------------------------->
    </visual>
<!------------------------------>
<!------------ TODO ------------>
<!-------------------------------
    <inertial>
      <mass>
      <pose>
      <inertia>
        <ixx>
        <ixy>
        <ixz>
        <iyy>
        <iyz>
        <izz>
-------------------------------->
  </link>

  <link name='Right_Triangle'>
    <self_collide>1</self_collide>
    <pose>0.0720 -0.4800 0.5820 0.0000 0.0000 0.0000</pose>
    <collision name='Right_Triangle_Collision'>
      <geometry>
        <mesh>
          <scale>0.0010 0.0010 0.0010</scale>
          <uri>model://msi_rover/meshes/Triangle_R.STL</uri>
        </mesh>
      </geometry>
<!------------------------------>
<!------------ TODO ------------>
<!-------------------------------
      <surface>
        <bounce>
          <restitution_coefficient>
-------------------------------->
    </collision>
    <visual name='Right_Triangle_Visual'>
      <geometry>
        <mesh>
          <scale>0.0010 0.0010 0.0010</scale>
          <uri>model://msi_rover/meshes/Triangle_R.STL</uri>
        </mesh>
      </geometry>
<!------------------------------>
<!------------ TODO ------------>
<!-------------------------------
      <material>
        <script>
          <uri>
          <name>
        <shader>
          <normal_map>
        <lighting>
        <ambient>
        <diffuse>
        <specular>
        <emissive>
-------------------------------->
    </visual>
<!------------------------------>
<!------------ TODO ------------>
<!-------------------------------
    <inertial>
      <mass>
      <pose>
      <inertia>
        <ixx>
        <ixy>
        <ixz>
        <iyy>
        <iyz>
        <izz>
-------------------------------->
  </link>

  <link name='Lower_Triangle_Rod'>
    <self_collide>1</self_collide>
    <pose>0.0000 -0.4930 0.4320 0.0000 0.0000 0.0000</pose>
    <collision name='Lower_Triangle_Rod_Collision'>
      <geometry>
        <mesh>
          <scale>0.0010 0.0010 0.0010</scale>
          <uri>model://msi_rover/meshes/Triangle_Rod.STL</uri>
        </mesh>
      </geometry>
<!------------------------------>
<!------------ TODO ------------>
<!-------------------------------
      <surface>
        <bounce>
          <restitution_coefficient>
-------------------------------->
    </collision>
    <visual name='Lower_Triangle_Rod_Visual'>
      <geometry>
        <mesh>
          <scale>0.0010 0.0010 0.0010</scale>
          <uri>model://msi_rover/meshes/Triangle_Rod.STL</uri>
        </mesh>
      </geometry>
<!------------------------------>
<!------------ TODO ------------>
<!-------------------------------
      <material>
        <script>
          <uri>
          <name>
        <shader>
          <normal_map>
        <lighting>
        <ambient>
        <diffuse>
        <specular>
        <emissive>
-------------------------------->
    </visual>
<!------------------------------>
<!------------ TODO ------------>
<!-------------------------------
    <inertial>
      <mass>
      <pose>
      <inertia>
        <ixx>
        <ixy>
        <ixz>
        <iyy>
        <iyz>
        <izz>
------------------------------->
  </link>

  <link name='Left_Diff_Support'>
    <self_collide>1</self_collide>
    <pose>-0.3085 -0.5340 0.5080 -0.4500 0.1500 0.0000</pose>
    <collision name='Left_Diff_Support_Collision'>
      <geometry>
        <cylinder>
          <radius>0.0050</radius>
          <length>0.1700</length>
        </cylinder>
      </geometry>
<!------------------------------>
<!------------ TODO ------------>
<!-------------------------------
      <surface>
        <bounce>
          <restitution_coefficient>
------------------------------->
    </collision>
    <visual name='Left_Diff_Support_Visual'>
      <geometry>
        <cylinder>
          <radius>0.0050</radius>
          <length>0.1700</length>
        </cylinder>
      </geometry>
<!------------------------------>
<!------------ TODO ------------>
<!-------------------------------
      <material>
        <script>
          <uri>
          <name>
        <shader>
          <normal_map>
        <lighting>
        <ambient>
        <diffuse>
        <specular>
        <emissive>
------------------------------->
    </visual>
<!------------------------------>
<!------------ TODO ------------>
<!-------------------------------
    <inertial>
      <mass>
      <pose>
      <inertia>
        <ixx>
        <ixy>
        <ixz>
        <iyy>
        <iyz>
        <izz>
------------------------------->
  </link>

  <link name='Right_Diff_Support'>
    <self_collide>1</self_collide>
    <pose>0.3085 -0.5340 0.5080 -0.4500 -0.1500 0.0000</pose>
    <collision name='Right_Diff_Support_Collision'>
      <geometry>
        <cylinder>
          <radius>0.0050</radius>
          <length>0.1700</length>
        </cylinder>
      </geometry>
<!------------------------------>
<!------------ TODO ------------>
<!-------------------------------
      <surface>
        <bounce>
          <restitution_coefficient>
------------------------------->
    </collision>
    <visual name='Right_Diff_Support_Visual'>
      <geometry>
        <cylinder>
          <radius>0.0050</radius>
          <length>0.1700</length>
        </cylinder>
      </geometry>
<!------------------------------>
<!------------ TODO ------------>
<!-------------------------------
      <material>
        <script>
          <uri>
          <name>
        <shader>
          <normal_map>
        <lighting>
        <ambient>
        <diffuse>
        <specular>
        <emissive>
------------------------------->
    </visual>
<!------------------------------>
<!------------ TODO ------------>
<!-------------------------------
    <inertial>
      <mass>
      <pose>
      <inertia>
        <ixx>
        <ixy>
        <ixz>
        <iyy>
        <iyz>
        <izz>
------------------------------->
  </link>

<!------------------------------------------------------------------------------------------>
<!---------------------------         Joints Subsection          --------------------------->
<!------------------------------------------------------------------------------------------>

  <joint type="revolute" name="Right_Lower_Triangle_Rod_Joint">
    <pose>0.0750 0.0000 0.0000 0.0000 0.0000 0.0000</pose>
    <child>Lower_Triangle_Rod</child>
    <parent>Right_Triangle</parent>
    <axis>
      <xyz>0 1 0</xyz>
<!------------------------------>
<!------------ TODO ------------>
<!-------------------------------
      <dynamics>
        <damping>
        <friction>
      <limit>
        <lower>
        <upper>
        <effort>
        <velocity>
        <stiffness>
        <dissipation>
------------------------------->
    </axis>
<!------------------------------>
<!------------ TODO ------------>
<!-------------------------------
    <physics>
      <ode>
        <provide_feedback>
        <cfm_damping>
        <implicit_spring_damper>
        <fudge_factor>
        <cfm>
        <erp>
        <bounce>
        <max_force>
        <velocity>
        <limit>
          <cfm>
          <erp>
        <suspension>
          <cfm>
          <erp>
------------------------------->
  </joint>

  <joint type="revolute" name="Left_Lower_Triangle_Rod_Joint">
    <pose>-0.0750 0.0000 0.0000 0.0000 0.0000 0.0000</pose>
    <child>Lower_Triangle_Rod</child>
    <parent>Left_Triangle</parent>
    <axis>
      <xyz>0 1 0</xyz>
<!------------------------------>
<!------------ TODO ------------>
<!-------------------------------
      <dynamics>
        <damping>
        <friction>
      <limit>
        <lower>
        <upper>
        <effort>
        <velocity>
        <stiffness>
        <dissipation>
------------------------------->
    </axis>
<!------------------------------>
<!------------ TODO ------------>
<!-------------------------------
    <physics>
      <ode>
        <provide_feedback>
        <cfm_damping>
        <implicit_spring_damper>
        <fudge_factor>
        <cfm>
        <erp>
        <bounce>
        <max_force>
        <velocity>
        <limit>
          <cfm>
          <erp>
        <suspension>
          <cfm>
          <erp>
------------------------------->
  </joint>

  <joint type="revolute" name="Right_Triangle_Joint">
    <pose>0.0000 0.0000 0.0000 0.0000 0.0000 0.0000</pose>
    <child>Right_Triangle</child>
    <parent>Chassis</parent>
    <axis>
      <xyz>0 1 0</xyz>
<!------------------------------>
<!------------ TODO ------------>
<!-------------------------------
      <dynamics>
        <damping>
        <friction>
      <limit>
        <lower>
        <upper>
        <effort>
        <velocity>
        <stiffness>
        <dissipation>
------------------------------->
    </axis>
<!------------------------------>
<!------------ TODO ------------>
<!-------------------------------
    <physics>
      <ode>
        <provide_feedback>
        <cfm_damping>
        <implicit_spring_damper>
        <fudge_factor>
        <cfm>
        <erp>
        <bounce>
        <max_force>
        <velocity>
        <limit>
          <cfm>
          <erp>
        <suspension>
          <cfm>
          <erp>
------------------------------->
  </joint>

  <joint type="revolute" name="Left_Triangle_Joint">
    <pose>0.0000 0.0000 0.0000 0.0000 0.0000 0.0000</pose>
    <child>Left_Triangle</child>
    <parent>Chassis</parent>
    <axis>
      <xyz>0 1 0</xyz>
<!------------------------------>
<!------------ TODO ------------>
<!-------------------------------
      <dynamics>
        <damping>
        <friction>
      <limit>
        <lower>
        <upper>
        <effort>
        <velocity>
        <stiffness>
        <dissipation>
------------------------------->
    </axis>
<!------------------------------>
<!------------ TODO ------------>
<!-------------------------------
    <physics>
      <ode>
        <provide_feedback>
        <cfm_damping>
        <implicit_spring_damper>
        <fudge_factor>
        <cfm>
        <erp>
        <bounce>
        <max_force>
        <velocity>
        <limit>
          <cfm>
          <erp>
        <suspension>
          <cfm>
          <erp>
------------------------------->
  </joint>

  <joint type="revolute2" name="Left_Diff_Support_Triangle_Joint">
    <pose>0.0000 0.0000 0.0880 0.0000 0.0000 0.0000</pose>
    <child>Left_Diff_Support</child>
    <parent>Left_Triangle</parent>
    <axis>
      <xyz>0 1 0</xyz>
<!------------------------------>
<!------------ TODO ------------>
<!-------------------------------
      <dynamics>
        <damping>
        <friction>
      <limit>
        <lower>
        <upper>
        <effort>
        <velocity>
        <stiffness>
        <dissipation>
------------------------------->
    </axis>
    <axis2>
      <xyz>0 0 1</xyz>
<!------------------------------>
<!------------ TODO ------------>
<!-------------------------------
      <dynamics>
        <damping>
        <friction>
      <limit>
        <lower>
        <upper>
        <effort>
        <velocity>
        <stiffness>
        <dissipation>
------------------------------->
    </axis2>
<!------------------------------>
<!------------ TODO ------------>
<!-------------------------------
    <physics>
      <ode>
        <provide_feedback>
        <cfm_damping>
        <implicit_spring_damper>
        <fudge_factor>
        <cfm>
        <erp>
        <bounce>
        <max_force>
        <velocity>
        <limit>
          <cfm>
          <erp>
        <suspension>
          <cfm>
          <erp>
------------------------------->
  </joint>

  <joint type="revolute2" name="Left_Diff_Support_Rocker_Joint">
    <pose>0.0000 0.0000 -0.0860 0.0000 0.0000 0.0000</pose>
    <child>Left_Diff_Support</child>
    <parent>Left_Rocker</parent>
    <axis>
      <xyz>1 0 0</xyz>
<!------------------------------>
<!------------ TODO ------------>
<!-------------------------------
      <dynamics>
        <damping>
        <friction>
      <limit>
        <lower>
        <upper>
        <effort>
        <velocity>
        <stiffness>
        <dissipation>
------------------------------->
    </axis>
    <axis2>
      <xyz>0 0 1</xyz>
<!------------------------------>
<!------------ TODO ------------>
<!-------------------------------
      <dynamics>
        <damping>
        <friction>
      <limit>
        <lower>
        <upper>
        <effort>
        <velocity>
        <stiffness>
        <dissipation>
------------------------------->
    </axis2>
<!------------------------------>
<!------------ TODO ------------>
<!-------------------------------
    <physics>
      <ode>
        <provide_feedback>
        <cfm_damping>
        <implicit_spring_damper>
        <fudge_factor>
        <cfm>
        <erp>
        <bounce>
        <max_force>
        <velocity>
        <limit>
          <cfm>
          <erp>
        <suspension>
          <cfm>
          <erp>
------------------------------->
  </joint>

  <joint type="revolute2" name="Right_Diff_Support_Triangle_Joint">
    <pose>0.0000 0.0000 0.0880 0.0000 0.0000 0.0000</pose>
    <child>Right_Diff_Support</child>
    <parent>Right_Triangle</parent>
    <axis>
      <xyz>0 1 0</xyz>
<!------------------------------>
<!------------ TODO ------------>
<!-------------------------------
      <dynamics>
        <damping>
        <friction>
      <limit>
        <lower>
        <upper>
        <effort>
        <velocity>
        <stiffness>
        <dissipation>
------------------------------->
    </axis>
    <axis2>
      <xyz>0 0 1</xyz>
<!------------------------------>
<!------------ TODO ------------>
<!-------------------------------
      <dynamics>
        <damping>
        <friction>
      <limit>
        <lower>
        <upper>
        <effort>
        <velocity>
        <stiffness>
        <dissipation>
------------------------------->
    </axis2>
<!------------------------------>
<!------------ TODO ------------>
<!-------------------------------
    <physics>
      <ode>
        <provide_feedback>
        <cfm_damping>
        <implicit_spring_damper>
        <fudge_factor>
        <cfm>
        <erp>
        <bounce>
        <max_force>
        <velocity>
        <limit>
          <cfm>
          <erp>
        <suspension>
          <cfm>
          <erp>
------------------------------->
  </joint>

  <joint type="revolute2" name="Right_Diff_Support_Rocker_Joint">
    <pose>0.0000 0.0000 -0.0860 0.0000 0.0000 0.0000</pose>
    <child>Right_Diff_Support</child>
    <parent>Right_Rocker</parent>
    <axis>
      <xyz>1 0 0</xyz>
<!------------------------------>
<!------------ TODO ------------>
<!-------------------------------
      <dynamics>
        <damping>
        <friction>
      <limit>
        <lower>
        <upper>
        <effort>
        <velocity>
        <stiffness>
        <dissipation>
------------------------------->
    </axis>
    <axis2>
      <xyz>0 0 1</xyz>
<!------------------------------>
<!------------ TODO ------------>
<!-------------------------------
      <dynamics>
        <damping>
        <friction>
      <limit>
        <lower>
        <upper>
        <effort>
        <velocity>
        <stiffness>
        <dissipation>
------------------------------->
    </axis2>
<!------------------------------>
<!------------ TODO ------------>
<!-------------------------------
    <physics>
      <ode>
        <provide_feedback>
        <cfm_damping>
        <implicit_spring_damper>
        <fudge_factor>
        <cfm>
        <erp>
        <bounce>
        <max_force>
        <velocity>
        <limit>
          <cfm>
          <erp>
        <suspension>
          <cfm>
          <erp>
------------------------------->
  </joint>

<!------------------------------------------------------------------------------------------>
<!------------------------------------------------------------------------------------------>
<!---------------------------   Triangle Support Assembly Ends   --------------------------->
<!------------------------------------------------------------------------------------------>
<!------------------------------------------------------------------------------------------>

</model>
</sdf>
